Workbook

Sheet How to use
B2: The Band of One Prompt Library: spreadsheet edition
B3: Works in Excel, Google Sheets (upload → Save as Google Sheets) and LibreOffice.
B5: 1. Search tab: type a keyword in the yellow box; pick a category to narrow results.
B6: 2. Prompts tab: the full library. Copy the Prompt column into your AI assistant and replace every [PLACEHOLDER].
B7: 3. Mark favorites with Y and keep your own tweaks in 'My notes'. The Categories tab counts your favorites.
B8: 4. Start with SET-01 (business brief) and SET-02 (voice profile). Most prompts work better with them.
B9: 5. Redact client names and confidential details before pasting (SET-03), and check your assistant's data settings.
B10: 6. You set prices, dates and promises. Check every draft before sending it to a client.
B12: Tip: grey columns M–N on the Prompts tab power the Search tab. Leave them in place.
B13: License: personal business use by the purchaser. Don't resell or redistribute. See LICENSE.txt.

Sheet Search
B1: The Band of One Prompt Library: Search
B2: Type a keyword (e.g., invoice, proposal, scope, testimonial) in the yellow box. Matching prompts appear below. Full text is on the Prompts tab.
B4: Keyword: | C4: invoice | E4: Category filter: | F4: All
B5: =COUNT(Prompts!$N$3:$N$102)&" matching prompt(s)" -> 9 matching prompt(s)
A7: # | B7: ID | C7: Title | D7: Category | E7: Objective
A8: =IF(1>COUNT(Prompts!$N$3:$N$102),"",1) -> 1 | B8: =IFERROR(INDEX(Prompts!$A$3:$A$102,MATCH(1,Prompts!$N$3:$N$102,0)),"") -> SET-03 | C8: =IFERROR(INDEX(Prompts!$C$3:$C$102,MATCH(1,Prompts!$N$3:$N$102,0)),"") -> Redaction check before pasting | D8: =IFERROR(INDEX(Prompts!$B$3:$B$102,MATCH(1,Prompts!$N$3:$N$102,0)),"") -> Setup & Foundations | E8: =IFERROR(INDEX(Prompts!$D$3:$D$102,MATCH(1,Prompts!$N$3:$N$102,0)),"") -> Catch client names and sensitive details before you share text with an AI tool.
A9: =IF(2>COUNT(Prompts!$N$3:$N$102),"",2) -> 2 | B9: =IFERROR(INDEX(Prompts!$A$3:$A$102,MATCH(2,Prompts!$N$3:$N$102,0)),"") -> PAY-01 | C9: =IFERROR(INDEX(Prompts!$C$3:$C$102,MATCH(2,Prompts!$N$3:$N$102,0)),"") -> Invoice email | D9: =IFERROR(INDEX(Prompts!$B$3:$B$102,MATCH(2,Prompts!$N$3:$N$102,0)),"") -> Invoicing & Getting Paid | E9: =IFERROR(INDEX(Prompts!$D$3:$D$102,MATCH(2,Prompts!$N$3:$N$102,0)),"") -> Send an invoice with a short, clear cover message.
A10: =IF(3>COUNT(Prompts!$N$3:$N$102),"",3) -> 3 | B10: =IFERROR(INDEX(Prompts!$A$3:$A$102,MATCH(3,Prompts!$N$3:$N$102,0)),"") -> PAY-02 | C10: =IFERROR(INDEX(Prompts!$C$3:$C$102,MATCH(3,Prompts!$N$3:$N$102,0)),"") -> Payment reminder sequence personalizer | D10: =IFERROR(INDEX(Prompts!$B$3:$B$102,MATCH(3,Prompts!$N$3:$N$102,0)),"") -> Invoicing & Getting Paid | E10: =IFERROR(INDEX(Prompts!$D$3:$D$102,MATCH(3,Prompts!$N$3:$N$102,0)),"") -> Send the right reminder, at the right stage, in the right tone.
A11: =IF(4>COUNT(Prompts!$N$3:$N$102),"",4) -> 4 | B11: =IFERROR(INDEX(Prompts!$A$3:$A$102,MATCH(4,Prompts!$N$3:$N$102,0)),"") -> PAY-04 | C11: =IFERROR(INDEX(Prompts!$C$3:$C$102,MATCH(4,Prompts!$N$3:$N$102,0)),"") -> Final notice (per your agreement) | D11: =IFERROR(INDEX(Prompts!$B$3:$B$102,MATCH(4,Prompts!$N$3:$N$102,0)),"") -> Invoicing & Getting Paid | E11: =IFERROR(INDEX(Prompts!$D$3:$D$102,MATCH(4,Prompts!$N$3:$N$102,0)),"") -> Send a formal final notice that states agreed next steps.
A12: =IF(5>COUNT(Prompts!$N$3:$N$102),"",5) -> 5 | B12: =IFERROR(INDEX(Prompts!$A$3:$A$102,MATCH(5,Prompts!$N$3:$N$102,0)),"") -> PAY-07 | C12: =IFERROR(INDEX(Prompts!$C$3:$C$102,MATCH(5,Prompts!$N$3:$N$102,0)),"") -> Monthly money review | D12: =IFERROR(INDEX(Prompts!$B$3:$B$102,MATCH(5,Prompts!$N$3:$N$102,0)),"") -> Invoicing & Getting Paid | E12: =IFERROR(INDEX(Prompts!$D$3:$D$102,MATCH(5,Prompts!$N$3:$N$102,0)),"") -> Get a quick picture of invoicing, collections and upcoming cash.
A13: =IF(6>COUNT(Prompts!$N$3:$N$102),"",6) -> 6 | B13: =IFERROR(INDEX(Prompts!$A$3:$A$102,MATCH(6,Prompts!$N$3:$N$102,0)),"") -> PAY-08 | C13: =IFERROR(INDEX(Prompts!$C$3:$C$102,MATCH(6,Prompts!$N$3:$N$102,0)),"") -> Payment received thank-you | D13: =IFERROR(INDEX(Prompts!$B$3:$B$102,MATCH(6,Prompts!$N$3:$N$102,0)),"") -> Invoicing & Getting Paid | E13: =IFERROR(INDEX(Prompts!$D$3:$D$102,MATCH(6,Prompts!$N$3:$N$102,0)),"") -> Confirm payment and strengthen the relationship.
A14: =IF(7>COUNT(Prompts!$N$3:$N$102),"",7) -> 7 | B14: =IFERROR(INDEX(Prompts!$A$3:$A$102,MATCH(7,Prompts!$N$3:$N$102,0)),"") -> RET-01 | C14: =IFERROR(INDEX(Prompts!$C$3:$C$102,MATCH(7,Prompts!$N$3:$N$102,0)),"") -> Project wrap-up & handover email | D14: =IFERROR(INDEX(Prompts!$B$3:$B$102,MATCH(7,Prompts!$N$3:$N$102,0)),"") -> Offboarding, Testimonials & Referrals | E14: =IFERROR(INDEX(Prompts!$D$3:$D$102,MATCH(7,Prompts!$N$3:$N$102,0)),"") -> Close a project cleanly with everything the client needs.
A15: =IF(8>COUNT(Prompts!$N$3:$N$102),"",8) -> 8 | B15: =IFERROR(INDEX(Prompts!$A$3:$A$102,MATCH(8,Prompts!$N$3:$N$102,0)),"") -> OPS-05 | C15: =IFERROR(INDEX(Prompts!$C$3:$C$102,MATCH(8,Prompts!$N$3:$N$102,0)),"") -> Weekly admin review assistant | D15: =IFERROR(INDEX(Prompts!$B$3:$B$102,MATCH(8,Prompts!$N$3:$N$102,0)),"") -> Systems, SOPs & Planning | E15: =IFERROR(INDEX(Prompts!$D$3:$D$102,MATCH(8,Prompts!$N$3:$N$102,0)),"") -> Run your weekly review faster, with nothing missed.
A16: =IF(9>COUNT(Prompts!$N$3:$N$102),"",9) -> 9 | B16: =IFERROR(INDEX(Prompts!$A$3:$A$102,MATCH(9,Prompts!$N$3:$N$102,0)),"") -> HARD-04 | C16: =IFERROR(INDEX(Prompts!$C$3:$C$102,MATCH(9,Prompts!$N$3:$N$102,0)),"") -> Ending a client relationship professionally | D16: =IFERROR(INDEX(Prompts!$B$3:$B$102,MATCH(9,Prompts!$N$3:$N$102,0)),"") -> Tough Conversations | E16: =IFERROR(INDEX(Prompts!$D$3:$D$102,MATCH(9,Prompts!$N$3:$N$102,0)),"") -> End an engagement clearly, kindly and according to your agreement.
A17: =IF(10>COUNT(Prompts!$N$3:$N$102),"",10) | B17: =IFERROR(INDEX(Prompts!$A$3:$A$102,MATCH(10,Prompts!$N$3:$N$102,0)),"") | C17: =IFERROR(INDEX(Prompts!$C$3:$C$102,MATCH(10,Prompts!$N$3:$N$102,0)),"") | D17: =IFERROR(INDEX(Prompts!$B$3:$B$102,MATCH(10,Prompts!$N$3:$N$102,0)),"") | E17: =IFERROR(INDEX(Prompts!$D$3:$D$102,MATCH(10,Prompts!$N$3:$N$102,0)),"")
A18: =IF(11>COUNT(Prompts!$N$3:$N$102),"",11) | B18: =IFERROR(INDEX(Prompts!$A$3:$A$102,MATCH(11,Prompts!$N$3:$N$102,0)),"") | C18: =IFERROR(INDEX(Prompts!$C$3:$C$102,MATCH(11,Prompts!$N$3:$N$102,0)),"") | D18: =IFERROR(INDEX(Prompts!$B$3:$B$102,MATCH(11,Prompts!$N$3:$N$102,0)),"") | E18: =IFERROR(INDEX(Prompts!$D$3:$D$102,MATCH(11,Prompts!$N$3:$N$102,0)),"")
A19: =IF(12>COUNT(Prompts!$N$3:$N$102),"",12) | B19: =IFERROR(INDEX(Prompts!$A$3:$A$102,MATCH(12,Prompts!$N$3:$N$102,0)),"") | C19: =IFERROR(INDEX(Prompts!$C$3:$C$102,MATCH(12,Prompts!$N$3:$N$102,0)),"") | D19: =IFERROR(INDEX(Prompts!$B$3:$B$102,MATCH(12,Prompts!$N$3:$N$102,0)),"") | E19: =IFERROR(INDEX(Prompts!$D$3:$D$102,MATCH(12,Prompts!$N$3:$N$102,0)),"")
A20: =IF(13>COUNT(Prompts!$N$3:$N$102),"",13) | B20: =IFERROR(INDEX(Prompts!$A$3:$A$102,MATCH(13,Prompts!$N$3:$N$102,0)),"") | C20: =IFERROR(INDEX(Prompts!$C$3:$C$102,MATCH(13,Prompts!$N$3:$N$102,0)),"") | D20: =IFERROR(INDEX(Prompts!$B$3:$B$102,MATCH(13,Prompts!$N$3:$N$102,0)),"") | E20: =IFERROR(INDEX(Prompts!$D$3:$D$102,MATCH(13,Prompts!$N$3:$N$102,0)),"")
A21: =IF(14>COUNT(Prompts!$N$3:$N$102),"",14) | B21: =IFERROR(INDEX(Prompts!$A$3:$A$102,MATCH(14,Prompts!$N$3:$N$102,0)),"") | C21: =IFERROR(INDEX(Prompts!$C$3:$C$102,MATCH(14,Prompts!$N$3:$N$102,0)),"") | D21: =IFERROR(INDEX(Prompts!$B$3:$B$102,MATCH(14,Prompts!$N$3:$N$102,0)),"") | E21: =IFERROR(INDEX(Prompts!$D$3:$D$102,MATCH(14,Prompts!$N$3:$N$102,0)),"")
A22: =IF(15>COUNT(Prompts!$N$3:$N$102),"",15) | B22: =IFERROR(INDEX(Prompts!$A$3:$A$102,MATCH(15,Prompts!$N$3:$N$102,0)),"") | C22: =IFERROR(INDEX(Prompts!$C$3:$C$102,MATCH(15,Prompts!$N$3:$N$102,0)),"") | D22: =IFERROR(INDEX(Prompts!$B$3:$B$102,MATCH(15,Prompts!$N$3:$N$102,0)),"") | E22: =IFERROR(INDEX(Prompts!$D$3:$D$102,MATCH(15,Prompts!$N$3:$N$102,0)),"")
A23: =IF(16>COUNT(Prompts!$N$3:$N$102),"",16) | B23: =IFERROR(INDEX(Prompts!$A$3:$A$102,MATCH(16,Prompts!$N$3:$N$102,0)),"") | C23: =IFERROR(INDEX(Prompts!$C$3:$C$102,MATCH(16,Prompts!$N$3:$N$102,0)),"") | D23: =IFERROR(INDEX(Prompts!$B$3:$B$102,MATCH(16,Prompts!$N$3:$N$102,0)),"") | E23: =IFERROR(INDEX(Prompts!$D$3:$D$102,MATCH(16,Prompts!$N$3:$N$102,0)),"")
A24: =IF(17>COUNT(Prompts!$N$3:$N$102),"",17) | B24: =IFERROR(INDEX(Prompts!$A$3:$A$102,MATCH(17,Prompts!$N$3:$N$102,0)),"") | C24: =IFERROR(INDEX(Prompts!$C$3:$C$102,MATCH(17,Prompts!$N$3:$N$102,0)),"") | D24: =IFERROR(INDEX(Prompts!$B$3:$B$102,MATCH(17,Prompts!$N$3:$N$102,0)),"") | E24: =IFERROR(INDEX(Prompts!$D$3:$D$102,MATCH(17,Prompts!$N$3:$N$102,0)),"")
A25: =IF(18>COUNT(Prompts!$N$3:$N$102),"",18) | B25: =IFERROR(INDEX(Prompts!$A$3:$A$102,MATCH(18,Prompts!$N$3:$N$102,0)),"") | C25: =IFERROR(INDEX(Prompts!$C$3:$C$102,MATCH(18,Prompts!$N$3:$N$102,0)),"") | D25: =IFERROR(INDEX(Prompts!$B$3:$B$102,MATCH(18,Prompts!$N$3:$N$102,0)),"") | E25: =IFERROR(INDEX(Prompts!$D$3:$D$102,MATCH(18,Prompts!$N$3:$N$102,0)),"")
A26: =IF(19>COUNT(Prompts!$N$3:$N$102),"",19) | B26: =IFERROR(INDEX(Prompts!$A$3:$A$102,MATCH(19,Prompts!$N$3:$N$102,0)),"") | C26: =IFERROR(INDEX(Prompts!$C$3:$C$102,MATCH(19,Prompts!$N$3:$N$102,0)),"") | D26: =IFERROR(INDEX(Prompts!$B$3:$B$102,MATCH(19,Prompts!$N$3:$N$102,0)),"") | E26: =IFERROR(INDEX(Prompts!$D$3:$D$102,MATCH(19,Prompts!$N$3:$N$102,0)),"")
A27: =IF(20>COUNT(Prompts!$N$3:$N$102),"",20) | B27: =IFERROR(INDEX(Prompts!$A$3:$A$102,MATCH(20,Prompts!$N$3:$N$102,0)),"") | C27: =IFERROR(INDEX(Prompts!$C$3:$C$102,MATCH(20,Prompts!$N$3:$N$102,0)),"") | D27: =IFERROR(INDEX(Prompts!$B$3:$B$102,MATCH(20,Prompts!$N$3:$N$102,0)),"") | E27: =IFERROR(INDEX(Prompts!$D$3:$D$102,MATCH(20,Prompts!$N$3:$N$102,0)),"")
A28: =IF(21>COUNT(Prompts!$N$3:$N$102),"",21) | B28: =IFERROR(INDEX(Prompts!$A$3:$A$102,MATCH(21,Prompts!$N$3:$N$102,0)),"") | C28: =IFERROR(INDEX(Prompts!$C$3:$C$102,MATCH(21,Prompts!$N$3:$N$102,0)),"") | D28: =IFERROR(INDEX(Prompts!$B$3:$B$102,MATCH(21,Prompts!$N$3:$N$102,0)),"") | E28: =IFERROR(INDEX(Prompts!$D$3:$D$102,MATCH(21,Prompts!$N$3:$N$102,0)),"")
A29: =IF(22>COUNT(Prompts!$N$3:$N$102),"",22) | B29: =IFERROR(INDEX(Prompts!$A$3:$A$102,MATCH(22,Prompts!$N$3:$N$102,0)),"") | C29: =IFERROR(INDEX(Prompts!$C$3:$C$102,MATCH(22,Prompts!$N$3:$N$102,0)),"") | D29: =IFERROR(INDEX(Prompts!$B$3:$B$102,MATCH(22,Prompts!$N$3:$N$102,0)),"") | E29: =IFERROR(INDEX(Prompts!$D$3:$D$102,MATCH(22,Prompts!$N$3:$N$102,0)),"")
A30: =IF(23>COUNT(Prompts!$N$3:$N$102),"",23) | B30: =IFERROR(INDEX(Prompts!$A$3:$A$102,MATCH(23,Prompts!$N$3:$N$102,0)),"") | C30: =IFERROR(INDEX(Prompts!$C$3:$C$102,MATCH(23,Prompts!$N$3:$N$102,0)),"") | D30: =IFERROR(INDEX(Prompts!$B$3:$B$102,MATCH(23,Prompts!$N$3:$N$102,0)),"") | E30: =IFERROR(INDEX(Prompts!$D$3:$D$102,MATCH(23,Prompts!$N$3:$N$102,0)),"")
A31: =IF(24>COUNT(Prompts!$N$3:$N$102),"",24) | B31: =IFERROR(INDEX(Prompts!$A$3:$A$102,MATCH(24,Prompts!$N$3:$N$102,0)),"") | C31: =IFERROR(INDEX(Prompts!$C$3:$C$102,MATCH(24,Prompts!$N$3:$N$102,0)),"") | D31: =IFERROR(INDEX(Prompts!$B$3:$B$102,MATCH(24,Prompts!$N$3:$N$102,0)),"") | E31: =IFERROR(INDEX(Prompts!$D$3:$D$102,MATCH(24,Prompts!$N$3:$N$102,0)),"")
A32: =IF(25>COUNT(Prompts!$N$3:$N$102),"",25) | B32: =IFERROR(INDEX(Prompts!$A$3:$A$102,MATCH(25,Prompts!$N$3:$N$102,0)),"") | C32: =IFERROR(INDEX(Prompts!$C$3:$C$102,MATCH(25,Prompts!$N$3:$N$102,0)),"") | D32: =IFERROR(INDEX(Prompts!$B$3:$B$102,MATCH(25,Prompts!$N$3:$N$102,0)),"") | E32: =IFERROR(INDEX(Prompts!$D$3:$D$102,MATCH(25,Prompts!$N$3:$N$102,0)),"")
A33: =IF(26>COUNT(Prompts!$N$3:$N$102),"",26) | B33: =IFERROR(INDEX(Prompts!$A$3:$A$102,MATCH(26,Prompts!$N$3:$N$102,0)),"") | C33: =IFERROR(INDEX(Prompts!$C$3:$C$102,MATCH(26,Prompts!$N$3:$N$102,0)),"") | D33: =IFERROR(INDEX(Prompts!$B$3:$B$102,MATCH(26,Prompts!$N$3:$N$102,0)),"") | E33: =IFERROR(INDEX(Prompts!$D$3:$D$102,MATCH(26,Prompts!$N$3:$N$102,0)),"")
A34: =IF(27>COUNT(Prompts!$N$3:$N$102),"",27) | B34: =IFERROR(INDEX(Prompts!$A$3:$A$102,MATCH(27,Prompts!$N$3:$N$102,0)),"") | C34: =IFERROR(INDEX(Prompts!$C$3:$C$102,MATCH(27,Prompts!$N$3:$N$102,0)),"") | D34: =IFERROR(INDEX(Prompts!$B$3:$B$102,MATCH(27,Prompts!$N$3:$N$102,0)),"") | E34: =IFERROR(INDEX(Prompts!$D$3:$D$102,MATCH(27,Prompts!$N$3:$N$102,0)),"")
A35: =IF(28>COUNT(Prompts!$N$3:$N$102),"",28) | B35: =IFERROR(INDEX(Prompts!$A$3:$A$102,MATCH(28,Prompts!$N$3:$N$102,0)),"") | C35: =IFERROR(INDEX(Prompts!$C$3:$C$102,MATCH(28,Prompts!$N$3:$N$102,0)),"") | D35: =IFERROR(INDEX(Prompts!$B$3:$B$102,MATCH(28,Prompts!$N$3:$N$102,0)),"") | E35: =IFERROR(INDEX(Prompts!$D$3:$D$102,MATCH(28,Prompts!$N$3:$N$102,0)),"")
A36: =IF(29>COUNT(Prompts!$N$3:$N$102),"",29) | B36: =IFERROR(INDEX(Prompts!$A$3:$A$102,MATCH(29,Prompts!$N$3:$N$102,0)),"") | C36: =IFERROR(INDEX(Prompts!$C$3:$C$102,MATCH(29,Prompts!$N$3:$N$102,0)),"") | D36: =IFERROR(INDEX(Prompts!$B$3:$B$102,MATCH(29,Prompts!$N$3:$N$102,0)),"") | E36: =IFERROR(INDEX(Prompts!$D$3:$D$102,MATCH(29,Prompts!$N$3:$N$102,0)),"")
A37: =IF(30>COUNT(Prompts!$N$3:$N$102),"",30) | B37: =IFERROR(INDEX(Prompts!$A$3:$A$102,MATCH(30,Prompts!$N$3:$N$102,0)),"") | C37: =IFERROR(INDEX(Prompts!$C$3:$C$102,MATCH(30,Prompts!$N$3:$N$102,0)),"") | D37: =IFERROR(INDEX(Prompts!$B$3:$B$102,MATCH(30,Prompts!$N$3:$N$102,0)),"") | E37: =IFERROR(INDEX(Prompts!$D$3:$D$102,MATCH(30,Prompts!$N$3:$N$102,0)),"")
A38: =IF(31>COUNT(Prompts!$N$3:$N$102),"",31) | B38: =IFERROR(INDEX(Prompts!$A$3:$A$102,MATCH(31,Prompts!$N$3:$N$102,0)),"") | C38: =IFERROR(INDEX(Prompts!$C$3:$C$102,MATCH(31,Prompts!$N$3:$N$102,0)),"") | D38: =IFERROR(INDEX(Prompts!$B$3:$B$102,MATCH(31,Prompts!$N$3:$N$102,0)),"") | E38: =IFERROR(INDEX(Prompts!$D$3:$D$102,MATCH(31,Prompts!$N$3:$N$102,0)),"")
A39: =IF(32>COUNT(Prompts!$N$3:$N$102),"",32) | B39: =IFERROR(INDEX(Prompts!$A$3:$A$102,MATCH(32,Prompts!$N$3:$N$102,0)),"") | C39: =IFERROR(INDEX(Prompts!$C$3:$C$102,MATCH(32,Prompts!$N$3:$N$102,0)),"") | D39: =IFERROR(INDEX(Prompts!$B$3:$B$102,MATCH(32,Prompts!$N$3:$N$102,0)),"") | E39: =IFERROR(INDEX(Prompts!$D$3:$D$102,MATCH(32,Prompts!$N$3:$N$102,0)),"")
A40: =IF(33>COUNT(Prompts!$N$3:$N$102),"",33) | B40: =IFERROR(INDEX(Prompts!$A$3:$A$102,MATCH(33,Prompts!$N$3:$N$102,0)),"") | C40: =IFERROR(INDEX(Prompts!$C$3:$C$102,MATCH(33,Prompts!$N$3:$N$102,0)),"") | D40: =IFERROR(INDEX(Prompts!$B$3:$B$102,MATCH(33,Prompts!$N$3:$N$102,0)),"") | E40: =IFERROR(INDEX(Prompts!$D$3:$D$102,MATCH(33,Prompts!$N$3:$N$102,0)),"")
A41: =IF(34>COUNT(Prompts!$N$3:$N$102),"",34) | B41: =IFERROR(INDEX(Prompts!$A$3:$A$102,MATCH(34,Prompts!$N$3:$N$102,0)),"") | C41: =IFERROR(INDEX(Prompts!$C$3:$C$102,MATCH(34,Prompts!$N$3:$N$102,0)),"") | D41: =IFERROR(INDEX(Prompts!$B$3:$B$102,MATCH(34,Prompts!$N$3:$N$102,0)),"") | E41: =IFERROR(INDEX(Prompts!$D$3:$D$102,MATCH(34,Prompts!$N$3:$N$102,0)),"")
A42: =IF(35>COUNT(Prompts!$N$3:$N$102),"",35) | B42: =IFERROR(INDEX(Prompts!$A$3:$A$102,MATCH(35,Prompts!$N$3:$N$102,0)),"") | C42: =IFERROR(INDEX(Prompts!$C$3:$C$102,MATCH(35,Prompts!$N$3:$N$102,0)),"") | D42: =IFERROR(INDEX(Prompts!$B$3:$B$102,MATCH(35,Prompts!$N$3:$N$102,0)),"") | E42: =IFERROR(INDEX(Prompts!$D$3:$D$102,MATCH(35,Prompts!$N$3:$N$102,0)),"")
...

Sheet Prompts
A1: All 100 prompts. Use the filter arrows, or the Search tab. Columns L–M are for your own notes.
A2: ID | B2: Category | C2: Title | D2: Objective | E2: When to use | F2: Inputs | G2: Prompt | H2: Output format | I2: Tip | J2: Pairs with | K2: Favorite (Y) | L2: My notes | M2: Match | N2: Match rank
A3: SET-01 | B3: Setup & Foundations | C3: Business brief builder | D3: Create a one-page description of your business that you reuse as context in every other prompt. | E3: Do this once when you start using AI for client admin; update it when your services or policies change. | F3: None: the AI interviews you | G3: Help me write a one-page "business brief" I can give an AI assistant before asking for help with client admin. Interview me with one question at a time (wait for each answer) covering: what I do and for whom; my 2–4 core services and typical project size; how I like to work (communication hours, response times, meeting preferences); my payment terms and policies; phrases or promises I never want used; and three examples of great client outcomes (described generally, no client names). When we're done, output the brief in this format: ## Who I am, ## Services, ## Ideal clients, ## How I work, ## Policies, ## Tone and words to avoid. Keep it under 450 words. | H3: A Markdown document with six headed sections, under 450 words. | I3: Save the result in your assistant's custom instructions or project knowledge, or paste it at the start of each chat. | J3: SET-02, SET-04 | M3: =IF(AND(OR(Search!$F$4="All",Search!$F$4=B3),OR(Search!$C$4="",ISNUMBER(SEARCH(Search!$C$4,A3&" "&B3&" "&C3&" "&D3&" "&E3&" "&G3)))),1,0) -> 0 | N3: =IF(M3=1,COUNTIF($M$3:M3,1),"")
A4: SET-02 | B4: Setup & Foundations | C4: Voice profile from writing samples | D4: Capture how you write so AI drafts sound like you, not like a generic assistant. | E4: After the business brief; refresh every few months. | F4: [NUMBER]: how many samples you're providing (3–5) [PASTE 3–5 REDACTED EMAILS]: emails you're happy with, names removed | G4: Below are [NUMBER] emails I wrote to clients (names removed). Analyze my writing style and produce a "voice profile" I can reuse in future prompts. Include: typical sentence length; greeting and sign-off habits; level of formality (1–5); words and phrases I use often; things I never do (e.g., exclamation marks, emojis, corporate phrases); how I deliver bad news; and 3 short "do this / not that" examples. Keep it under 250 words and don't invent traits that aren't in the samples. """[PASTE 3–5 REDACTED EMAILS]""" | H4: A short profile (≤250 words) with bullet points and 3 do/don't examples. | I4: Choose emails that cover different situations (good news, a delay, a follow-up) so the profile is well-rounded. | J4: SET-01 | M4: =IF(AND(OR(Search!$F$4="All",Search!$F$4=B4),OR(Search!$C$4="",ISNUMBER(SEARCH(Search!$C$4,A4&" "&B4&" "&C4&" "&D4&" "&E4&" "&G4)))),1,0) -> 0 | N4: =IF(M4=1,COUNTIF($M$3:M4,1),"")
A5: SET-03 | B5: Setup & Foundations | C5: Redaction check before pasting | D5: Catch client names and sensitive details before you share text with an AI tool. | E5: While you're building the redaction habit, or on long documents such as transcripts and threads. | F5: [PASTE TEXT]: the text you plan to use | G5: I'm about to paste text into an AI assistant. Act as a careful privacy reviewer. Scan the text between the triple quotes and list every item that could identify a person or company or expose sensitive data (names, emails, phone numbers, addresses, account numbers, prices tied to named clients, health/legal/HR details, passwords or links with tokens). Then return a redacted version that replaces each item with a clear placeholder like [CLIENT NAME] or [INVOICE AMOUNT]. Don't change anything else. """[PASTE TEXT]""" | H5: 1) A bulleted list of sensitive items found. 2) The full redacted text. | I5: Running this inside the same assistant means the text has already been shared, so use it on text you've already partly redacted, or on non-confidential material while you learn. | J5: SET-01 | M5: =IF(AND(OR(Search!$F$4="All",Search!$F$4=B5),OR(Search!$C$4="",ISNUMBER(SEARCH(Search!$C$4,A5&" "&B5&" "&C5&" "&D5&" "&E5&" "&G5)))),1,0) -> 1 | N5: =IF(M5=1,COUNTIF($M$3:M5,1),"") -> 1
A6: SET-04 | B6: Setup & Foundations | C6: Custom instructions writer | D6: Turn your business brief and voice profile into compact standing instructions for your AI assistant. | E6: When your assistant has a "custom instructions", "project instructions" or "personalization" field with a character limit. | F6: [BUSINESS BRIEF] [VOICE PROFILE] [CHARACTER LIMIT]: e.g., 1,500 characters | G6: Using my business brief and voice profile below, write standing instructions for my AI assistant in under [CHARACTER LIMIT] characters. Split them into two parts: (1) "What you should know about me" (business facts, services, policies) and (2) "How you should respond" (tone, format preferences, rules). Always include these rules: never invent prices, dates or facts about clients; mark missing information as [NEED INFO]; keep client emails under 200 words unless I ask otherwise; suggest one clarifying question when my request is ambiguous. Count the characters and confirm the total. Business brief: """[BUSINESS BRIEF]""" Voice profile: """[VOICE PROFILE]""" | H6: Two labeled blocks of plain text plus a character count. | I6: Test the instructions with one real task (e.g., LEAD-01) and tweak. | J6: SET-01, SET-02 | M6: =IF(AND(OR(Search!$F$4="All",Search!$F$4=B6),OR(Search!$C$4="",ISNUMBER(SEARCH(Search!$C$4,A6&" "&B6&" "&C6&" "&D6&" "&E6&" "&G6)))),1,0) -> 0 | N6: =IF(M6=1,COUNTIF($M$3:M6,1),"")
A7: SET-05 | B7: Setup & Foundations | C7: Service menu clarifier | D7: Describe each of your services clearly, with who it's for, what's included, and what's not. | E7: Before writing proposals or a services page; when clients keep misunderstanding what you offer. | F7: [SERVICES]: rough notes on each service [IDEAL CLIENT] | G7: I'm a [PROFESSION] serving [IDEAL CLIENT]. Here are rough notes about my services: """[SERVICES]""". For each service, produce: a plain-language name; a one-sentence promise focused on the client's outcome; who it's for and not for; what's included (bullets); what's not included (bullets); typical timeline; what I need from the client. Keep prices exactly as I wrote them; if I didn't give a price, write [PRICE]. Then point out any overlaps or gaps between services that could confuse a buyer. | H7: One block per service with consistent headings, then a short "overlaps and gaps" list. | I7: Reuse the "not included" bullets in your proposals (PROP-06). | J7: PROP-06, MKT-05 | M7: =IF(AND(OR(Search!$F$4="All",Search!$F$4=B7),OR(Search!$C$4="",ISNUMBER(SEARCH(Search!$C$4,A7&" "&B7&" "&C7&" "&D7&" "&E7&" "&G7)))),1,0) -> 0 | N7: =IF(M7=1,COUNTIF($M$3:M7,1),"")
A8: SET-06 | B8: Setup & Foundations | C8: Client FAQ builder | D8: Build a set of answers to the questions clients ask again and again. | E8: When you notice you're typing the same explanations; before creating an onboarding packet. | F8: [REPEATED QUESTIONS]: questions clients often ask [BUSINESS BRIEF] | G8: Using my business brief """[BUSINESS BRIEF]""", draft clear answers to these frequently asked client questions: """[REPEATED QUESTIONS]""". For each: a direct answer in 2–4 sentences in my voice, any policy it depends on, and where the answer should live (proposal, welcome email, onboarding doc, website FAQ). If my brief doesn't contain the information needed, write [NEED INFO: what's missing] instead of guessing. Add up to 5 more questions clients in my field commonly ask that I haven't listed. | H8: A table with columns Question, Answer, Depends on, Where it lives; then a list of suggested extra questions. | I8: Paste the finished FAQ into your onboarding document and link it in your welcome email. | J8: ONB-04 | M8: =IF(AND(OR(Search!$F$4="All",Search!$F$4=B8),OR(Search!$C$4="",ISNUMBER(SEARCH(Search!$C$4,A8&" "&B8&" "&C8&" "&D8&" "&E8&" "&G8)))),1,0) -> 0 | N8: =IF(M8=1,COUNTIF($M$3:M8,1),"")
A9: SET-07 | B9: Setup & Foundations | C9: Communication policy writer | D9: Write a friendly, clear policy for response times, channels, meetings and feedback rounds. | E9: Before onboarding new clients, or when boundaries have been slipping. | F9: [WORKING HOURS] [RESPONSE TIME] [CHANNELS]: e.g., email for decisions, Slack for quick questions [FEEDBACK ROUNDS] | G9: Write a short "How we'll work together" section for my client onboarding materials. Details: working hours [WORKING HOURS]; typical response time [RESPONSE TIME]; channels [CHANNELS]; meetings [MEETING PREFERENCES]; feedback process [FEEDBACK ROUNDS]; urgent issues [HOW TO FLAG URGENT]. Make it warm and confident, not defensive. Explain the reason behind each norm in one short clause (e.g., "so nothing gets lost"). Under 200 words, using bullets. | H9: A heading plus 5–7 bullets, under 200 words. | I9: Put this in your welcome email (ONB-01) and your onboarding document. | J9: ONB-01, ONB-04 | M9: =IF(AND(OR(Search!$F$4="All",Search!$F$4=B9),OR(Search!$C$4="",ISNUMBER(SEARCH(Search!$C$4,A9&" "&B9&" "&C9&" "&D9&" "&E9&" "&G9)))),1,0) -> 0 | N9: =IF(M9=1,COUNTIF($M$3:M9,1),"")
A10: SET-08 | B10: Setup & Foundations | C10: Tool stack audit | D10: Find overlapping or unused software and decide what to keep, replace or cancel. | E10: Quarterly, or when subscription costs creep up. | F10: [TOOL LIST]: tool, what I use it for, monthly cost, how often I use it | G10: Here is the list of software tools I pay for or rely on in my one-person business: """[TOOL LIST]""". Analyze it and produce: (1) overlaps: tools doing the same job; (2) tools I barely use relative to their cost; (3) jobs that seem to have no tool or rely on manual work; (4) a recommendation for each tool: Keep, Downgrade, Replace with [free option I already have], or Cancel, with one-line reasoning. Don't recommend new paid tools unless a gap clearly justifies it, and say what the free alternative is. Finish with the total monthly cost before and after your recommendations, based only on the prices I gave. | H10: Four short sections, then a table (Tool, Recommendation, Reason, Monthly cost), then before/after totals. | I10: Check cancellation terms and data export before cancelling anything. | J10: OPS-07 | M10: =IF(AND(OR(Search!$F$4="All",Search!$F$4=B10),OR(Search!$C$4="",ISNUMBER(SEARCH(Search!$C$4,A10&" "&B10&" "&C10&" "&D10&" "&E10&" "&G10)))),1,0) -> 0 | N10: =IF(M10=1,COUNTIF($M$3:M10,1),"")
A11: LEAD-01 | B11: Leads & Inquiries | C11: Reply to a new inquiry | D11: Answer a new inquiry quickly and qualify the lead. | E11: Within one business day of any new inquiry by email, form or DM. | F11: [BUSINESS BRIEF] and [VOICE PROFILE] [PASTE INQUIRY] [BOOKING LINK] | G11: Here is my business brief and voice profile: [PASTE]. A potential client sent this inquiry (redacted): """[PASTE INQUIRY]""". Draft a reply under 150 words that: thanks them and references one specific detail from their message; answers any direct question they asked (if I haven't given you the answer, write [NEED INFO] instead of guessing); asks the 2–3 most useful qualifying questions for my services; and ends with my booking link [BOOKING LINK]. Match my voice profile. Don't mention prices unless they asked and my brief includes them. | H11: A ready-to-edit email with subject line, under 150 words. | I11: Save your best version as an email template and only use AI for the personalized first two lines. | J11: LEAD-02, DISC-01 | M11: =IF(AND(OR(Search!$F$4="All",Search!$F$4=B11),OR(Search!$C$4="",ISNUMBER(SEARCH(Search!$C$4,A11&" "&B11&" "&C11&" "&D11&" "&E11&" "&G11)))),1,0) -> 0 | N11: =IF(M11=1,COUNTIF($M$3:M11,1),"")
A12: LEAD-02 | B12: Leads & Inquiries | C12: Lead fit scorecard | D12: Decide quickly whether a lead is a good fit before investing time. | E12: When an inquiry is vague, oddly sized or outside your usual work. | F12: [IDEAL CLIENT CRITERIA] [LEAD INFO]: inquiry + anything you know | G12: My ideal client criteria: """[IDEAL CLIENT CRITERIA]""". Here's what I know about a new lead (redacted): """[LEAD INFO]""". Score the lead from 1–5 on: budget fit, timeline fit, scope fit, decision-maker access, and red flags (5 = no red flags). Explain each score in one line, quoting the evidence. Recommend one of: Book a call, Ask 2 questions first, Refer elsewhere, Politely decline. If there isn't enough information to score a criterion, say "Unknown" and give the question that would resolve it. | H12: A 5-row table (Criterion, Score, Evidence) plus a one-line recommendation and up to 3 questions. | I12: This is a thinking aid. You make the final call, and politeness costs nothing even when you decline. | J12: LEAD-01, LEAD-06 | M12: =IF(AND(OR(Search!$F$4="All",Search!$F$4=B12),OR(Search!$C$4="",ISNUMBER(SEARCH(Search!$C$4,A12&" "&B12&" "&C12&" "&D12&" "&E12&" "&G12)))),1,0) -> 0 | N12: =IF(M12=1,COUNTIF($M$3:M12,1),"")
A13: LEAD-03 | B13: Leads & Inquiries | C13: Follow up an inquiry that went quiet | D13: Re-open a conversation with a lead who stopped replying, without pressure. | E13: 3–7 days after your last message with no response. | F13: [LAST MESSAGE SUMMARY] [DAYS SINCE] [BOOKING LINK] | G13: A potential client stopped replying [DAYS SINCE] days ago. Our last exchange: """[LAST MESSAGE SUMMARY]""". Write two alternative follow-up emails in my voice [VOICE PROFILE], each under 90 words: Version A adds something useful (a relevant tip, example or resource related to their project, without inventing facts about them); Version B is a simple, friendly check-in that makes it easy to say "not now". Neither should guilt-trip or imply urgency that doesn't exist. Include my booking link [BOOKING LINK] once. | H13: Two labeled email drafts with subject lines. | I13: Send at most two follow-ups, then stop and mark the lead "cold" in your tracker. | J13: LEAD-01 | M13: =IF(AND(OR(Search!$F$4="All",Search!$F$4=B13),OR(Search!$C$4="",ISNUMBER(SEARCH(Search!$C$4,A13&" "&B13&" "&C13&" "&D13&" "&E13&" "&G13)))),1,0) -> 0 | N13: =IF(M13=1,COUNTIF($M$3:M13,1),"")
A14: LEAD-04 | B14: Leads & Inquiries | C14: Referral request to a happy client or peer | D14: Ask for referrals in a specific, easy-to-act-on way. | E14: After a successful project or a positive comment from a client or peer. | F14: [RELATIONSHIP]: client or peer, and context [IDEAL REFERRAL]: who you want to be introduced to | G14: Write a short message asking [RELATIONSHIP] for referrals. Be specific about who I'm looking for: [IDEAL REFERRAL]. Make it easy: include a two-sentence blurb about me that they can forward as-is, and say it's completely fine if nobody comes to mind. Keep it under 120 words, warm and not salesy, in my voice [VOICE PROFILE]. Don't offer a referral fee unless I've specified one here: [REFERRAL INCENTIVE OR "NONE"]. | H14: One message plus a separate forwardable blurb (2 sentences). | I14: Specific asks ("a physio clinic owner planning a new website") get more introductions than "anyone who needs help". | J14: RET-05 | M14: =IF(AND(OR(Search!$F$4="All",Search!$F$4=B14),OR(Search!$C$4="",ISNUMBER(SEARCH(Search!$C$4,A14&" "&B14&" "&C14&" "&D14&" "&E14&" "&G14)))),1,0) -> 0 | N14: =IF(M14=1,COUNTIF($M$3:M14,1),"")
... A102: HARD-04 | B102: Tough Conversations | C102: Ending a client relationship professionally | D102: End an engagement clearly, kindly and according to your agreement. | E102: When a working relationship isn't working for either side. | F102: [REASON]: your private reason; share only what's appropriate [TERMINATION TERMS]: from your agreement [HANDOVER PLAN] | G102: Draft a message ending my work with a client. Termination terms from our agreement: """[TERMINATION TERMS]""". Handover plan: """[HANDOVER PLAN]""". Share only this reason: [SHAREABLE REASON]. Structure: clear decision; effective date; what I'll complete or hand over and when; final invoice or refund per the agreement; good wishes. Under 170 words, respectful, no blame. Add a reminder for me to check the agreement and, if unsure, get professional advice before sending. | H102: One message plus a reminder note to me. | I102: Keep everything in writing and deliver the handover exactly as promised. | J102: RET-01 | M102: =IF(AND(OR(Search!$F$4="All",Search!$F$4=B102),OR(Search!$C$4="",ISNUMBER(SEARCH(Search!$C$4,A102&" "&B102&" "&C102&" "&D102&" "&E102&" "&G102)))),1,0) -> 1 | N102: =IF(M102=1,COUNTIF($M$3:M102,1),"") -> 9

Sheet Categories
A1: Categories
A2: Category | B2: ID prefix | C2: Prompts | D2: Your favorites | E2: What it's for
A3: All | C3: =COUNTA(Prompts!$A$3:$A$102) -> 100 | D3: =COUNTIF(Prompts!$K$3:$K$102,"Y") -> 0
A4: Setup & Foundations | B4: SET | C4: =COUNTIF(Prompts!$B$3:$B$102,A4) -> 8 | D4: =COUNTIFS(Prompts!$B$3:$B$102,A4,Prompts!$K$3:$K$102,"Y") -> 0 | E4: Give your AI assistant the context it needs, once: your business brief, your voice, and your privacy habits.
A5: Leads & Inquiries | B5: LEAD | C5: =COUNTIF(Prompts!$B$3:$B$102,A5) -> 10 | D5: =COUNTIFS(Prompts!$B$3:$B$102,A5,Prompts!$K$3:$K$102,"Y") -> 0 | E5: Reply fast, qualify well, and follow up without sounding pushy.
A6: Discovery & Sales Calls | B6: DISC | C6: =COUNTIF(Prompts!$B$3:$B$102,A6) -> 8 | D6: =COUNTIFS(Prompts!$B$3:$B$102,A6,Prompts!$K$3:$K$102,"Y") -> 0 | E6: Prepare, run and follow up on discovery calls that lead to good-fit projects.
A7: Proposals & Pricing | B7: PROP | C7: =COUNTIF(Prompts!$B$3:$B$102,A7) -> 12 | D7: =COUNTIFS(Prompts!$B$3:$B$102,A7,Prompts!$K$3:$K$102,"Y") -> 0 | E7: Draft specific proposals, structure options and protect your scope. You set the prices; AI never does.
A8: Onboarding | B8: ONB | C8: =COUNTIF(Prompts!$B$3:$B$102,A8) -> 10 | D8: =COUNTIFS(Prompts!$B$3:$B$102,A8,Prompts!$K$3:$K$102,"Y") -> 0 | E8: Turn a 'yes' into a smooth, professional start.
A9: Delivery & Client Communication | B9: DEL | C9: =COUNTIF(Prompts!$B$3:$B$102,A9) -> 14 | D9: =COUNTIFS(Prompts!$B$3:$B$102,A9,Prompts!$K$3:$K$102,"Y") -> 0 | E9: Updates, feedback, delays, scope changes and meeting notes: the everyday communication of client work.
A10: Invoicing & Getting Paid | B10: PAY | C10: =COUNTIF(Prompts!$B$3:$B$102,A10) -> 8 | D10: =COUNTIFS(Prompts!$B$3:$B$102,A10,Prompts!$K$3:$K$102,"Y") -> 0 | E10: Invoice clearly and follow up on a predictable, respectful schedule.
A11: Offboarding, Testimonials & Referrals | B11: RET | C11: =COUNTIF(Prompts!$B$3:$B$102,A11) -> 8 | D11: =COUNTIFS(Prompts!$B$3:$B$102,A11,Prompts!$K$3:$K$102,"Y") -> 0 | E11: Finish well, earn honest testimonials and keep relationships warm.
A12: Content & Marketing | B12: MKT | C12: =COUNTIF(Prompts!$B$3:$B$102,A12) -> 10 | D12: =COUNTIFS(Prompts!$B$3:$B$102,A12,Prompts!$K$3:$K$102,"Y") -> 0 | E12: Turn your expertise into useful content without inventing results or hype.
A13: Systems, SOPs & Planning | B13: OPS | C13: =COUNTIF(Prompts!$B$3:$B$102,A13) -> 8 | D13: =COUNTIFS(Prompts!$B$3:$B$102,A13,Prompts!$K$3:$K$102,"Y") -> 0 | E13: Document processes, decide what to automate and plan your weeks and quarters.
A14: Tough Conversations | B14: HARD | C14: =COUNTIF(Prompts!$B$3:$B$102,A14) -> 4 | D14: =COUNTIFS(Prompts!$B$3:$B$102,A14,Prompts!$K$3:$K$102,"Y") -> 0 | E14: Calm, honest language for the conversations nobody enjoys.
