Workbook

Sheet Calendar
A1: Band of One: 60-day social calendar (Month 1 content → Month 2 product launch)
A2: Start date (Day 1): | E2: Type your Day 1 date in the yellow cell; every date below updates. Launch day = Day 38 (Month 2, day 8). Nothing is scheduled or posted automatically.
A4: Day | B4: Date | C4: Weekday | D4: Campaign month | E4: Channel | F4: Type | G4: ID | H4: Title / concept | I4: Hook | J4: Link | K4: Caption / post text | L4: Hashtags | M4: Graphic | N4: Status | O4: Posted URL | P4: Notes
A5: 1 | B5: =IF($C$2="","",$C$2+A5-1) | C5: =IF(B5="","",TEXT(B5,"ddd")) | D5: Month 1: Content | E5: LinkedIn | F5: Educational post | G5: C-E01 | H5: The onboarding checklist | J5: /blog/client-onboarding-checklist/ | K5: Most client problems start in week one, not week ten. A 7-step onboarding checklist that prevents most of them: 1. Proposal accepted in writing 2. Agreement signed (scope, exclusions, payment terms, revisions) 3. Deposit invoice sent. Work starts when it clears 4. Welcome email with numbered next steps 5. Intake form instead of 20 questions by email 6. Communication norms agreed: where, when, how fast 7. Kickoff call with an agenda, plus a written summary the same day Same steps, same order, every client. After three clients you'll know which questions to add to your form. Full checklist + free tools: [link] | L5: #freelancetips #clientexperience #smallbusinesstips #solopreneur #consultantlife | N5: Draft
A6: 1 | B6: =IF($C$2="","",$C$2+A6-1) | C6: =IF(B6="","",TEXT(B6,"ddd")) | D6: Month 1: Content | E6: TikTok / Reels / Shorts (+ LinkedIn native) | F6: Short video | G6: C-V01 | H6: The 30-minute onboarding checklist | I6: Most client problems start in the first week, not the last. | J6: /blog/client-onboarding-checklist/ | K6: Most client problems start in week one. Here's the 7-step onboarding checklist I'd give every freelancer: same steps, same order, every client. Full checklist + free tools at the link in bio. | L6: #freelancetips #clientexperience #smallbusinesstips #solopreneur #consultantlife | M6: graphics/video_covers/C-V01.png | N6: Draft
A7: 2 | B7: =IF($C$2="","",$C$2+A7-1) | C7: =IF(B7="","",TEXT(B7,"ddd")) | D7: Month 1: Content | E7: LinkedIn + Instagram | F7: Promotional post | G7: C-P01 | H7: Free starter kit launch | J7: /newsletter/ | K7: New and free: the Client Admin Starter Kit. 10 AI prompts for the admin you do every week (inquiry replies, call summaries, proposals, welcome emails, weekly updates, scope changes, payment reminders, testimonial requests), plus a printable 30-minute weekly review checklist. Works with free AI plans. Get it here: [link] | L7: #bandofone #solopreneur #freelancer #virtualassistant #consultant | M7: graphics/promo_cards/C-P01.png | N7: Draft
A8: 2 | B8: =IF($C$2="","",$C$2+A8-1) | C8: =IF(B8="","",TEXT(B8,"ddd")) | D8: Month 1: Content | E8: TikTok / Reels / Shorts (+ LinkedIn native) | F8: Short video | G8: C-V02 | H8: Never paste these into ChatGPT | I8: Five things that should never go into an AI chat, even for client work. | J8: /blog/client-data-privacy-ai/ | K8: Using AI for client emails? Five things that never go in the chat, plus the 5-second redaction habit for everything else. The settings for ChatGPT, Claude and Gemini are in the full guide (link in bio). | L8: #AItools #ChatGPTtips #AIforBusiness #promptengineering #freelancetips | M8: graphics/video_covers/C-V02.png | N8: Draft
A9: 3 | B9: =IF($C$2="","",$C$2+A9-1) | C9: =IF(B9="","",TEXT(B9,"ddd")) | D9: Month 1: Content | E9: Instagram | F9: Educational post (carousel) | G9: C-E02 | H9: 5 things never to paste into AI | J9: /blog/client-data-privacy-ai/ | K9: Save this for the next time you're about to paste an email thread into an AI chat. The redaction habit takes five seconds, and the full privacy routine (with where to find the ChatGPT, Claude and Gemini settings) is at the link in bio. | L9: #AItools #ChatGPTtips #AIforBusiness #promptengineering #freelancetips | M9: graphics/carousels/C-E02_01.png | N9: Draft
A10: 3 | B10: =IF($C$2="","",$C$2+A10-1) | C10: =IF(B10="","",TEXT(B10,"ddd")) | D10: Month 1: Content | E10: TikTok / Reels / Shorts (+ LinkedIn native) | F10: Short video | G10: C-V03 | H10: The 5-stage payment reminder schedule | I10: Chasing invoices feels personal because you haven't decided the schedule in advance. | J10: /blog/payment-reminder-schedule/ | K10: Chasing invoices gets easier when the schedule is decided in advance. Five stages, five templates, from a friendly heads-up to a final notice. Link in bio. | L10: #freelancebusiness #invoicing #smallbusinessowner #getpaid #solopreneur | M10: graphics/video_covers/C-V03.png | N10: Draft
A11: 4 | B11: =IF($C$2="","",$C$2+A11-1) | C11: =IF(B11="","",TEXT(B11,"ddd")) | D11: Month 1: Content | E11: TikTok / Reels / Shorts (+ LinkedIn native) | F11: Short video | G11: C-V04 | H11: Why your AI emails sound generic | I11: Your AI emails sound generic because the AI knows nothing about your business. | J11: /blog/ai-business-brief/ | K11: If your AI drafts sound generic, it's usually missing context, not a better prompt. Build a one-page business brief once (the interview prompt is in the link in bio) and every draft starts from your reality. | L11: #AItools #ChatGPTtips #AIforBusiness #promptengineering #freelancetips | M11: graphics/video_covers/C-V04.png | N11: Draft
A12: 5 | B12: =IF($C$2="","",$C$2+A12-1) | C12: =IF(B12="","",TEXT(B12,"ddd")) | D12: Month 1: Content | E12: LinkedIn | F12: Educational post | G12: C-E03 | H12: Payment reminders, decided once | J12: /blog/payment-reminder-schedule/ | K12: Chasing invoices feels personal because most of us decide what to do each time. Decide once: A: 3 days before due: friendly heads-up (catches wrong-inbox problems) B: due date: short reminder C: +7 days: "anything holding it up?" D: +14 days: ask for a payment date in writing E: +30 days: final notice, stating only what's in your agreement It matters: in Bonsai's data from 100,000+ freelancers, 29% of invoices were paid at least a day late (Bonsai, updated Jan 2026). Templates for all five stages: [link] | L12: #freelancebusiness #invoicing #smallbusinessowner #getpaid #solopreneur | N12: Draft
A13: 5 | B13: =IF($C$2="","",$C$2+A13-1) | C13: =IF(B13="","",TEXT(B13,"ddd")) | D13: Month 1: Content | E13: TikTok / Reels / Shorts (+ LinkedIn native) | F13: Short video | G13: C-V05 | H13: The weekly client update in 4 headings | I13: Clients chase you when they don't know what's happening. | J13: /blog/weekly-client-update-template/ | K13: The five-minute weekly client update: four headings, same day every week. 'Needed from you (with dates)' is the line that does the heavy lifting. Template + AI prompt at the link in bio. | L13: #freelancetips #clientexperience #smallbusinesstips #solopreneur #consultantlife | M13: graphics/video_covers/C-V05.png | N13: Draft
A14: 6 | B14: =IF($C$2="","",$C$2+A14-1) | C14: =IF(B14="","",TEXT(B14,"ddd")) | D14: Month 1: Content | E14: LinkedIn + Instagram | F14: Promotional post | G14: C-P02 | H14: Free invoice tracker | J14: /blog/track-invoices-in-a-spreadsheet/ | K14: Free download: a small spreadsheet that tells you which payment reminder to send (A–E) for every invoice. Tested against eight scenarios before we published it. Works in Google Sheets and Excel. No sign-up needed. Formulas explained + download: [link] | L14: #freelancebusiness #invoicing #smallbusinessowner #getpaid #solopreneur | M14: graphics/promo_cards/C-P02.png | N14: Draft
A15: 6 | B15: =IF($C$2="","",$C$2+A15-1) | C15: =IF(B15="","",TEXT(B15,"ddd")) | D15: Month 1: Content | E15: TikTok / Reels / Shorts (+ LinkedIn native) | F15: Short video | G15: C-V06 | H15: Score before you automate | I15: Don't automate your admin yet. Score it first. | J15: /blog/what-to-automate-first/ | K15: Before you buy an automation tool, score your admin tasks: (times per month × minutes) × repeatability ÷ risk. Often the best first fix is a template, not a robot. Method + example at the link in bio. | L15: #systemsthinking #SOP #productivitytips #solopreneur #businesssystems | M15: graphics/video_covers/C-V06.png | N15: Draft
A16: 7 | B16: =IF($C$2="","",$C$2+A16-1) | C16: =IF(B16="","",TEXT(B16,"ddd")) | D16: Month 1: Content | E16: Instagram | F16: Educational post (carousel) | G16: C-E04 | H16: The weekly client update | J16: /blog/weekly-client-update-template/ | K16: Four headings, same day every week. The 'Needed from you' line turns vague delays into specific requests with dates. Template + AI prompt at the link in bio. | L16: #freelancetips #clientexperience #smallbusinesstips #solopreneur #consultantlife | M16: graphics/carousels/C-E04_01.png | N16: Draft
A17: 7 | B17: =IF($C$2="","",$C$2+A17-1) | C17: =IF(B17="","",TEXT(B17,"ddd")) | D17: Month 1: Content | E17: TikTok / Reels / Shorts (+ LinkedIn native) | F17: Short video | G17: C-V07 | H17: What Band of One is (intro) | I17: If you run a service business on your own, you're also the whole back office. | J17: /newsletter/ | K17: Band of One: practical AI systems for businesses of one. Workflows, templates and honest tool notes for freelancers, consultants, coaches and VAs. Start with the free starter kit (link in bio). | L17: #bandofone #solopreneur #freelancer #virtualassistant #consultant | M17: graphics/video_covers/C-V07.png | N17: Draft
A18: 8 | B18: =IF($C$2="","",$C$2+A18-1) | C18: =IF(B18="","",TEXT(B18,"ddd")) | D18: Month 1: Content | E18: TikTok / Reels / Shorts (+ LinkedIn native) | F18: Short video | G18: C-V08 | H18: Deposits: the one sentence that matters | I18: The most important sentence in your payment terms is seven words long. | J18: /blog/deposits-and-payment-terms/ | K18: Deposits, milestones and payment terms: decide them once and put them in every proposal. The wording (plus a full example) is at the link in bio. General info, not legal advice. | L18: #freelancebusiness #invoicing #smallbusinessowner #getpaid #solopreneur | M18: graphics/video_covers/C-V08.png | N18: Draft
A19: 9 | B19: =IF($C$2="","",$C$2+A19-1) | C19: =IF(B19="","",TEXT(B19,"ddd")) | D19: Month 1: Content | E19: LinkedIn | F19: Educational post | G19: C-E05 | H19: Why AI drafts sound generic | J19: /blog/ai-business-brief/ | K19: If your AI drafts sound generic, the problem usually isn't the prompt. It's missing context. The assistant doesn't know your services, your terms, or the promises you never make. So it fills the gaps with the average of everything it's read. Fix it once with a one-page business brief: → Who I am → Services → Ideal clients → How I work → Policies → Tone and words to avoid Let the AI interview you to build it (about 20 minutes), then reuse it everywhere. The interview prompt: [link] | L19: #AItools #ChatGPTtips #AIforBusiness #promptengineering #freelancetips | N19: Draft
A20: 9 | B20: =IF($C$2="","",$C$2+A20-1) | C20: =IF(B20="","",TEXT(B20,"ddd")) | D20: Month 1: Content | E20: TikTok / Reels / Shorts (+ LinkedIn native) | F20: Short video | G20: C-V09 | H20: Make AI sound like you | I20: You can spot an AI email from the first line. | J20: /blog/make-ai-sound-like-you/ | K20: "I hope this email finds you well." Here's how to make AI drafts sound like you instead: a voice profile built from 3–5 of your real emails. Prompt and example at the link in bio. | L20: #AItools #ChatGPTtips #AIforBusiness #promptengineering #freelancetips | M20: graphics/video_covers/C-V09.png | N20: Draft
A21: 10 | B21: =IF($C$2="","",$C$2+A21-1) | C21: =IF(B21="","",TEXT(B21,"ddd")) | D21: Month 1: Content | E21: LinkedIn | F21: Promotional post | G21: C-P03 | H21: Why we label tested vs researched | J21: /editorial-policy/ | K21: A small promise from Band of One: every tool article is labeled. Tested = we used it for the job described, and we say how. Researched = based on official docs and pricing pages, with the date checked. No "we tested 50 tools". No income claims. No fake testimonials. Our editorial policy: [link] | L21: #bandofone #solopreneur #freelancer #virtualassistant #consultant | M21: graphics/promo_cards/C-P03.png | N21: Draft
A22: 10 | B22: =IF($C$2="","",$C$2+A22-1) | C22: =IF(B22="","",TEXT(B22,"ddd")) | D22: Month 1: Content | E22: TikTok / Reels / Shorts (+ LinkedIn native) | F22: Short video | G22: C-V10 | H22: Scope creep: offer a choice | I22: Scope creep isn't a people problem. It's a visibility problem. | J22: /blog/scope-creep-email-templates/ | K22: Scope creep is a visibility problem. Name the change, offer two options, wait for a yes. Four email templates (including the "quick favor") at the link in bio. | L22: #freelancetips #clientexperience #smallbusinesstips #solopreneur #consultantlife | M22: graphics/video_covers/C-V10.png | N22: Draft
A23: 11 | B23: =IF($C$2="","",$C$2+A23-1) | C23: =IF(B23="","",TEXT(B23,"ddd")) | D23: Month 1: Content | E23: Instagram | F23: Educational post (carousel) | G23: C-E06 | H23: Score your admin before you automate | J23: /blog/what-to-automate-first/ | K23: The scoring method that stops you spending a weekend automating a task you do twice a month. Worked example at the link in bio. | L23: #systemsthinking #SOP #productivitytips #solopreneur #businesssystems | M23: graphics/carousels/C-E06_01.png | N23: Draft
A24: 11 | B24: =IF($C$2="","",$C$2+A24-1) | C24: =IF(B24="","",TEXT(B24,"ddd")) | D24: Month 1: Content | E24: TikTok / Reels / Shorts (+ LinkedIn native) | F24: Short video | G24: C-V11 | H24: Spreadsheet formula: which reminder is due | I24: One spreadsheet formula can tell you which payment reminder to send. | J24: /blog/track-invoices-in-a-spreadsheet/ | K24: A spreadsheet that tells you which payment reminder to send (A–E). Tested against eight scenarios; works in Google Sheets and Excel. Free starter file at the link in bio. | L24: #freelancebusiness #invoicing #smallbusinessowner #getpaid #solopreneur | M24: graphics/video_covers/C-V11.png | N24: Draft
A25: 12 | B25: =IF($C$2="","",$C$2+A25-1) | C25: =IF(B25="","",TEXT(B25,"ddd")) | D25: Month 1: Content | E25: Instagram | F25: Promotional post | G25: C-P04 | H25: Newsletter: one idea a week | J25: /newsletter/ | K25: One practical admin-system idea a week, by email. Short, useful, no hype. Plus the free starter kit when you sign up. Unsubscribe any time. Link in bio. | L25: #bandofone #solopreneur #freelancer #virtualassistant #consultant | M25: graphics/promo_cards/C-P04.png | N25: Draft
A26: 12 | B26: =IF($C$2="","",$C$2+A26-1) | C26: =IF(B26="","",TEXT(B26,"ddd")) | D26: Month 1: Content | E26: TikTok / Reels / Shorts (+ LinkedIn native) | F26: Short video | G26: C-V12 | H26: The weekly admin review | I26: Admin with no set time leaks into every day. | J26: /blog/weekly-admin-review/ | K26: One 45-minute appointment a week keeps admin out of the rest of your week. The five-block agenda (plus an AI prompt that pre-sorts it) is at the link in bio. | L26: #systemsthinking #SOP #productivitytips #solopreneur #businesssystems | M26: graphics/video_covers/C-V12.png | N26: Draft
A27: 13 | B27: =IF($C$2="","",$C$2+A27-1) | C27: =IF(B27="","",TEXT(B27,"ddd")) | D27: Month 1: Content | E27: LinkedIn | F27: Educational post | G27: C-E07 | H27: Scope creep in one email | J27: /blog/scope-creep-email-templates/ | K27: Scope creep rarely arrives as a big request. It's "while you're in there…" The goal isn't to say no. It's to make the change visible: "Thanks for the idea. It's outside the current scope, so two options: 1) Add it now: [price], and launch moves to [date] 2) Keep the launch date and do it as a follow-up phase I'll hold off on this piece until I hear which you prefer." That last line matters most. Starting "just to be helpful" makes it very hard to charge for later. Four templates (including the "quick favor"): [link] | L27: #freelancetips #clientexperience #smallbusinesstips #solopreneur #consultantlife | N27: Draft
A28: 13 | B28: =IF($C$2="","",$C$2+A28-1) | C28: =IF(B28="","",TEXT(B28,"ddd")) | D28: Month 1: Content | E28: TikTok / Reels / Shorts (+ LinkedIn native) | F28: Short video | G28: C-V13 | H28: AI proposals: the one rule | I28: Never let AI set your prices. | J28: /blog/write-a-proposal-with-ai/ | K28: AI can draft proposals that don't sound generic, but it should never set your prices or promises. Seven-part structure + prompt at the link in bio. | L28: #freelancetips #clientexperience #smallbusinesstips #solopreneur #consultantlife | M28: graphics/video_covers/C-V13.png | N28: Draft
A29: 14 | B29: =IF($C$2="","",$C$2+A29-1) | C29: =IF(B29="","",TEXT(B29,"ddd")) | D29: Month 1: Content | E29: LinkedIn + Instagram | F29: Promotional post | G29: C-P05 | H29: Series: Getting Paid | J29: /category/getting-paid/ | K29: This month's Getting Paid series, all free: → The 5-stage payment reminder schedule → Deposits, milestones and payment terms → What every invoice should include → Tracking invoices in a spreadsheet (tested formulas) Start here: [link] | L29: #freelancebusiness #invoicing #smallbusinessowner #getpaid #solopreneur | M29: graphics/promo_cards/C-P05.png | N29: Draft
A30: 14 | B30: =IF($C$2="","",$C$2+A30-1) | C30: =IF(B30="","",TEXT(B30,"ddd")) | D30: Month 1: Content | E30: TikTok / Reels / Shorts (+ LinkedIn native) | F30: Short video | G30: C-V14 | H30: Starter kit walkthrough | I30: Ten prompts for the admin you do every week, free. | J30: /newsletter/ | K30: The free Client Admin Starter Kit: 10 AI prompts for the admin you do every week + a printable 30-minute weekly review checklist. Link in bio. | L30: #bandofone #solopreneur #freelancer #virtualassistant #consultant | M30: graphics/video_covers/C-V14.png | N30: Draft
A31: 15 | B31: =IF($C$2="","",$C$2+A31-1) | C31: =IF(B31="","",TEXT(B31,"ddd")) | D31: Month 1: Content | E31: Instagram | F31: Educational post (carousel) | G31: C-E08 | H31: What every invoice needs | J31: /blog/what-to-include-on-an-invoice/ | K31: Remove every reason for your invoice to be set aside. Full checklist, plus the UK government's list as an example baseline, at the link in bio. | L31: #freelancebusiness #invoicing #smallbusinessowner #getpaid #solopreneur | M31: graphics/carousels/C-E08_01.png | N31: Draft
A32: 15 | B32: =IF($C$2="","",$C$2+A32-1) | C32: =IF(B32="","",TEXT(B32,"ddd")) | D32: Month 1: Content | E32: TikTok / Reels / Shorts (+ LinkedIn native) | F32: Short video | G32: C-V15 | H32: Invoice details that prevent late payment | I32: Late payments often start with the invoice itself. | J32: /blog/what-to-include-on-an-invoice/ | K32: Remove every reason for your invoice to be set aside: clear description, real due date, easy payment, right recipient. Full checklist (and where to check your country's rules) at the link in bio. | L32: #freelancebusiness #invoicing #smallbusinessowner #getpaid #solopreneur | M32: graphics/video_covers/C-V15.png | N32: Draft
A33: 16 | B33: =IF($C$2="","",$C$2+A33-1) | C33: =IF(B33="","",TEXT(B33,"ddd")) | D33: Month 1: Content | E33: LinkedIn | F33: Promotional post | G33: C-P06 | H33: AI, Done Right series | J33: /category/ai-done-right/ | K33: Using AI for client work without the generic emails or the privacy worries. Four free guides: → Keep client data private (ChatGPT, Claude, Gemini settings) → The one-page AI business brief → Make AI drafts sound like you → 12 client-email prompts with guardrails [link] | L33: #AItools #ChatGPTtips #AIforBusiness #promptengineering #freelancetips | M33: graphics/promo_cards/C-P06.png | N33: Draft
A34: 16 | B34: =IF($C$2="","",$C$2+A34-1) | C34: =IF(B34="","",TEXT(B34,"ddd")) | D34: Month 1: Content | E34: TikTok / Reels / Shorts (+ LinkedIn native) | F34: Short video | G34: C-V16 | H34: SOPs for a one-person business | I34: SOPs aren't just for companies with an operations team. | J34: /blog/sop-template-one-person-business/ | K34: A one-page SOP template for solo businesses, plus the AI prompt that turns rough notes into a finished SOP (and flags gaps instead of inventing steps). Link in bio. | L34: #systemsthinking #SOP #productivitytips #solopreneur #businesssystems | M34: graphics/video_covers/C-V16.png | N34: Draft
A35: 17 | B35: =IF($C$2="","",$C$2+A35-1) | C35: =IF(B35="","",TEXT(B35,"ddd")) | D35: Month 1: Content | E35: LinkedIn | F35: Educational post | G35: C-E09 | H35: Voice profile | J35: /blog/make-ai-sound-like-you/ | K35: "I hope this email finds you well." "I'm thrilled to…" "Please don't hesitate to reach out." Clients can spot AI emails from the first line. A voice profile fixes most of it. Paste 3–5 emails you actually wrote (names removed) and ask the AI to describe: • typical sentence length • greeting and sign-off habits • formality (1–5) • things you never do • how you deliver bad news • 3 "do this / not that" examples Key instruction: "Don't invent traits that aren't in the samples." Prompt + example: [link] | L35: #AItools #ChatGPTtips #AIforBusiness #promptengineering #freelancetips | N35: Draft
A36: 17 | B36: =IF($C$2="","",$C$2+A36-1) | C36: =IF(B36="","",TEXT(B36,"ddd")) | D36: Month 1: Content | E36: TikTok / Reels / Shorts (+ LinkedIn native) | F36: Short video | G36: C-V17 | H36: Make vs Zapier vs n8n in 45 seconds | I36: Make, Zapier or n8n? Here's the honest short version. | J36: /blog/make-vs-zapier-vs-n8n/ | K36: Make vs Zapier vs n8n for freelancers: simplest start, best budget multi-step, most control. Researched from official pricing pages (checked Sept 2026), not hands-on tested. Full comparison at the link in bio. | L36: #nocode #automation #smallbusinesstools #freelancetools #solopreneur | M36: graphics/video_covers/C-V17.png | N36: Draft
A37: 18 | B37: =IF($C$2="","",$C$2+A37-1) | C37: =IF(B37="","",TEXT(B37,"ddd")) | D37: Month 1: Content | E37: TikTok / Reels / Shorts (+ LinkedIn native) | F37: Short video | G37: C-V18 | H37: A prompt that says [NEED INFO] | I37: The most useful words in any AI prompt: 'write NEED INFO instead of guessing'. | J37: /blog/ai-prompts-for-client-emails/ | K37: One line that stops AI inventing details in client emails: "write [NEED INFO] instead of guessing." 12 client-email prompts with guardrails at the link in bio. | L37: #AItools #ChatGPTtips #AIforBusiness #promptengineering #freelancetips | M37: graphics/video_covers/C-V18.png | N37: Draft
A38: 19 | B38: =IF($C$2="","",$C$2+A38-1) | C38: =IF(B38="","",TEXT(B38,"ddd")) | D38: Month 1: Content | E38: Instagram | F38: Educational post (carousel) | G38: C-E10 | H38: The 45-minute weekly admin review | J38: /blog/weekly-admin-review/ | K38: Give admin one appointment a week and it stops leaking into every day. Agenda + an AI prompt that pre-sorts it at the link in bio. | L38: #systemsthinking #SOP #productivitytips #solopreneur #businesssystems | M38: graphics/carousels/C-E10_01.png | N38: Draft
A39: 19 | B39: =IF($C$2="","",$C$2+A39-1) | C39: =IF(B39="","",TEXT(B39,"ddd")) | D39: Month 1: Content | E39: TikTok / Reels / Shorts (+ LinkedIn native) | F39: Short video | G39: C-V19 | H39: Free newsletter tools: what actually differs | I39: If you want a free welcome email sequence, the free plans differ a lot. | J39: /blog/mailerlite-vs-kit-vs-beehiiv/ | K39: MailerLite vs Kit vs beehiiv for a service business newsletter: the free-plan difference that matters is automation. Researched from official pricing pages (Sept 2026). Link in bio. | L39: #nocode #automation #smallbusinesstools #freelancetools #solopreneur | M39: graphics/video_covers/C-V19.png | N39: Draft
A40: 20 | B40: =IF($C$2="","",$C$2+A40-1) | C40: =IF(B40="","",TEXT(B40,"ddd")) | D40: Month 1: Content | E40: Instagram | F40: Promotional post | G40: C-P07 | H40: Save this: prompt guardrails | J40: /blog/ai-prompts-for-client-emails/ | K40: Save this post: 4 guardrail lines for any AI assistant used for client work → never invent prices/dates/facts · write [NEED INFO] instead of guessing · under 200 words · ask one question if unclear. 12 prompts built on them at the link in bio. | L40: #AItools #ChatGPTtips #AIforBusiness #promptengineering #freelancetips | M40: graphics/promo_cards/C-P07.png | N40: Draft
A41: 20 | B41: =IF($C$2="","",$C$2+A41-1) | C41: =IF(B41="","",TEXT(B41,"ddd")) | D41: Month 1: Content | E41: TikTok / Reels / Shorts (+ LinkedIn native) | F41: Short video | G41: C-V20 | H41: The kickoff summary email | I41: The email you send after the kickoff call saves more arguments than any contract clause. | J41: /blog/client-onboarding-checklist/ | K41: The kickoff summary email: same day, five parts, and your written answer to questions that come up in week six. Part of the onboarding checklist at the link in bio. | L41: #freelancetips #clientexperience #smallbusinesstips #solopreneur #consultantlife | M41: graphics/video_covers/C-V20.png | N41: Draft
...

Sheet Summary
A1: Counts by type and status (formulas)
A3: Type | B3: Planned | C3: Posted | D3: Remaining
A4: Educational post | B4: =COUNTIF(Calendar!$F$5:$F$114,A4) -> 16 | C4: =COUNTIFS(Calendar!$F$5:$F$114,A4,Calendar!$N$5:$N$114,"Posted") -> 0 | D4: =B4-C4 -> 16
A5: Educational post (carousel) | B5: =COUNTIF(Calendar!$F$5:$F$114,A5) -> 14 | C5: =COUNTIFS(Calendar!$F$5:$F$114,A5,Calendar!$N$5:$N$114,"Posted") -> 0 | D5: =B5-C5 -> 14
A6: Promotional post | B6: =COUNTIF(Calendar!$F$5:$F$114,A6) -> 20 | C6: =COUNTIFS(Calendar!$F$5:$F$114,A6,Calendar!$N$5:$N$114,"Posted") -> 0 | D6: =B6-C6 -> 20
A7: Short video | B7: =COUNTIF(Calendar!$F$5:$F$114,A7) -> 60 | C7: =COUNTIFS(Calendar!$F$5:$F$114,A7,Calendar!$N$5:$N$114,"Posted") -> 0 | D7: =B7-C7 -> 60
A8: Total | B8: =SUM(B4:B7) -> 110 | C8: =SUM(C4:C7) -> 0 | D8: =SUM(D4:D7) -> 110
