Workbook

Sheet Start Here
B1: The Client Desk
B2: A simple command center for a business of one · by Band of One · v1.0
B4: What this is | C4: One workbook for clients, pipeline, projects, invoices and payment reminders, plus the admin audit, prompt log, SOP index and weekly review from The Solo Admin Playbook.
B5: Works in | C5: Microsoft Excel 2010 or later · Google Sheets (upload, then File → Save as Google Sheets) · LibreOffice Calc. No macros, no add-ins.
B6: Colour key | C6: YELLOW cells = type here. GREY cells = calculated, don't type over them. SLATE headers = helper columns the dashboard needs (leave them).
B7: Step 1 · Settings | C7: Open the Settings tab. Enter your business name, default payment terms and currency code. Edit the Services list.
B8: Step 2 · Clear the sample | C8: Rows marked SAMPLE in the Notes column are a fictional example business. Select their YELLOW cells and press Delete. Don't delete whole rows, so the formulas stay in place.
B9: Step 3 · Add clients | C9: Clients & Pipeline: one row per client or lead. Choose a Stage from the dropdown and always fill in 'Next action' and 'Next action date'.
B10: Step 4 · Log invoices | C10: Invoices & Follow-ups: enter issue date, amount and (optionally) terms. Due date, status, days overdue and the next reminder stage (A–E) calculate automatically. When you send a reminder, record its stage and date.
B11: Step 5 · Run your audit | C11: Admin Audit: list recurring tasks, then score repeatability and risk. The highest-ranked tasks appear on the Dashboard. Re-estimate minutes after you change a task to measure real savings.
B12: Weekly habit | C12: Every week (Settings → review day) open the Dashboard, work through 'Next client actions' and 'Invoices needing a reminder', then log your numbers on the Weekly Review tab.
B13: Reminder stages | C13: A = heads-up 3 days before due · B = due date · C = 7 days overdue · D = 14 days overdue · E = 30 days overdue (final notice). Change the timing on Settings. Templates are in The Solo Admin Playbook, Chapter 9.
B14: Dates | C14: Type dates as YYYY-MM-DD (e.g., 2026-10-15) or in your system's date format. 'Today' comes from your computer clock unless you set an override on Settings.
B15: Capacity | C15: Clients: 150 rows · Invoices: 200 rows · Projects: 100 rows · Audit: 40 rows. To add more, copy the last row down (formulas copy with it).
... B18: License | C18: Personal business use by the purchaser. Don't resell or redistribute the file. See LICENSE.txt in your download.

Sheet Dashboard
B1: The Client Desk
B2: ="Dashboard for "&Settings!$C$5&" · as of "&TEXT(Settings!$C$6,"d mmm yyyy") -> Dashboard for Sam Rivera Design (sample) · as of 24 Sep 2026
B4: Active clients | D4: ="Weighted pipeline ("&Settings!$C$8&")" -> Weighted pipeline (USD) | G4: ="Outstanding ("&Settings!$C$8&")" -> Outstanding (USD) | I4: ="Overdue ("&Settings!$C$8&")" -> Overdue (USD) | L4: Reminders to send
B5: =COUNTIF('Clients & Pipeline'!$K$5:$K$154,"Active") -> 2 | D5: =SUMIFS('Clients & Pipeline'!$J$5:$J$154,'Clients & Pipeline'!$K$5:$K$154,"Pipeline") -> 3590 | G5: =SUMIFS('Invoices & Follow-ups'!$J$5:$J$204,'Invoices & Follow-ups'!$K$5:$K$204,"<>Paid") -> 5180 | I5: =SUMIFS('Invoices & Follow-ups'!$J$5:$J$204,'Invoices & Follow-ups'!$K$5:$K$204,"Overdue") -> 1830 | L5: =SUM('Invoices & Follow-ups'!$S$5:$S$204) -> 4
B8: Follow-ups overdue | D8: Follow-ups this week | G8: ="Invoiced this month ("&Settings!$C$8&")" -> Invoiced this month (USD) | I8: ="Collected this month ("&Settings!$C$8&")" -> Collected this month (USD) | L8: Admin hours / month
B9: =COUNTIF('Clients & Pipeline'!$Q$5:$Q$154,"Overdue") -> 1 | D9: =COUNTIF('Clients & Pipeline'!$Q$5:$Q$154,"Due this week") -> 4 | G9: =SUMIFS('Invoices & Follow-ups'!$G$5:$G$204,'Invoices & Follow-ups'!$D$5:$D$204,">="&DATE(YEAR(Settings!$C$6),MONTH(Settings!$C$6),1),'Invoices & Follow-ups'!$D$5:$D$204,"<="&Settings!$C$6) -> 4650 | I9: =SUMIFS('Invoices & Follow-ups'!$H$5:$H$204,'Invoices & Follow-ups'!$I$5:$I$204,">="&DATE(YEAR(Settings!$C$6),MONTH(Settings!$C$6),1),'Invoices & Follow-ups'!$I$5:$I$204,"<="&Settings!$C$6) -> 100 | L9: ='Admin Audit'!$Q$6 -> 23.333333
B12: Next client actions | G12: Invoices needing a reminder
B13: Client | C13: Next action | D13: Date | E13: Status | G13: Client | H13: Invoice # | I13: Balance | J13: Action
B14: =IFERROR(INDEX('Clients & Pipeline'!$B$5:$B$154,MATCH(1,'Clients & Pipeline'!$V$5:$V$154,0)),"") -> Brightside Physio | C14: =IFERROR(INDEX('Clients & Pipeline'!$N$5:$N$154,MATCH(1,'Clients & Pipeline'!$V$5:$V$154,0)),"") -> Send call summary | D14: =IFERROR(INDEX('Clients & Pipeline'!$O$5:$O$154,MATCH(1,'Clients & Pipeline'!$V$5:$V$154,0)),"") -> 46288 | E14: =IFERROR(INDEX('Clients & Pipeline'!$Q$5:$Q$154,MATCH(1,'Clients & Pipeline'!$V$5:$V$154,0)),"") -> Overdue | G14: =IFERROR(INDEX('Invoices & Follow-ups'!$B$5:$B$204,MATCH(1,'Invoices & Follow-ups'!$T$5:$T$204,0)),"") -> Maple Street Bakery | H14: =IFERROR(INDEX('Invoices & Follow-ups'!$A$5:$A$204,MATCH(1,'Invoices & Follow-ups'!$T$5:$T$204,0)),"") -> 2026-019 | I14: =IFERROR(INDEX('Invoices & Follow-ups'!$J$5:$J$204,MATCH(1,'Invoices & Follow-ups'!$T$5:$T$204,0)),"") -> 450 | J14: =IFERROR(INDEX('Invoices & Follow-ups'!$Q$5:$Q$204,MATCH(1,'Invoices & Follow-ups'!$T$5:$T$204,0)),"") -> Send E now
B15: =IFERROR(INDEX('Clients & Pipeline'!$B$5:$B$154,MATCH(2,'Clients & Pipeline'!$V$5:$V$154,0)),"") -> Cedar Yoga | C15: =IFERROR(INDEX('Clients & Pipeline'!$N$5:$N$154,MATCH(2,'Clients & Pipeline'!$V$5:$V$154,0)),"") -> Reply to inquiry | D15: =IFERROR(INDEX('Clients & Pipeline'!$O$5:$O$154,MATCH(2,'Clients & Pipeline'!$V$5:$V$154,0)),"") -> 46289 | E15: =IFERROR(INDEX('Clients & Pipeline'!$Q$5:$Q$154,MATCH(2,'Clients & Pipeline'!$V$5:$V$154,0)),"") -> Due this week | G15: =IFERROR(INDEX('Invoices & Follow-ups'!$B$5:$B$204,MATCH(2,'Invoices & Follow-ups'!$T$5:$T$204,0)),"") -> Harbor Dental Studio | H15: =IFERROR(INDEX('Invoices & Follow-ups'!$A$5:$A$204,MATCH(2,'Invoices & Follow-ups'!$T$5:$T$204,0)),"") -> 2026-023 | I15: =IFERROR(INDEX('Invoices & Follow-ups'!$J$5:$J$204,MATCH(2,'Invoices & Follow-ups'!$T$5:$T$204,0)),"") -> 180 | J15: =IFERROR(INDEX('Invoices & Follow-ups'!$Q$5:$Q$204,MATCH(2,'Invoices & Follow-ups'!$T$5:$T$204,0)),"") -> Send D now
B16: =IFERROR(INDEX('Clients & Pipeline'!$B$5:$B$154,MATCH(3,'Clients & Pipeline'!$V$5:$V$154,0)),"") -> Harbor Dental Studio | C16: =IFERROR(INDEX('Clients & Pipeline'!$N$5:$N$154,MATCH(3,'Clients & Pipeline'!$V$5:$V$154,0)),"") -> Send weekly update | D16: =IFERROR(INDEX('Clients & Pipeline'!$O$5:$O$154,MATCH(3,'Clients & Pipeline'!$V$5:$V$154,0)),"") -> 46291 | E16: =IFERROR(INDEX('Clients & Pipeline'!$Q$5:$Q$154,MATCH(3,'Clients & Pipeline'!$V$5:$V$154,0)),"") -> Due this week | G16: =IFERROR(INDEX('Invoices & Follow-ups'!$B$5:$B$204,MATCH(3,'Invoices & Follow-ups'!$T$5:$T$204,0)),"") -> Oak & Pine Law | H16: =IFERROR(INDEX('Invoices & Follow-ups'!$A$5:$A$204,MATCH(3,'Invoices & Follow-ups'!$T$5:$T$204,0)),"") -> 2026-021 | I16: =IFERROR(INDEX('Invoices & Follow-ups'!$J$5:$J$204,MATCH(3,'Invoices & Follow-ups'!$T$5:$T$204,0)),"") -> 600 | J16: =IFERROR(INDEX('Invoices & Follow-ups'!$Q$5:$Q$204,MATCH(3,'Invoices & Follow-ups'!$T$5:$T$204,0)),"") -> Send B now
B17: =IFERROR(INDEX('Clients & Pipeline'!$B$5:$B$154,MATCH(4,'Clients & Pipeline'!$V$5:$V$154,0)),"") -> Oak & Pine Law | C17: =IFERROR(INDEX('Clients & Pipeline'!$N$5:$N$154,MATCH(4,'Clients & Pipeline'!$V$5:$V$154,0)),"") -> Proposal follow-up (day 7) | D17: =IFERROR(INDEX('Clients & Pipeline'!$O$5:$O$154,MATCH(4,'Clients & Pipeline'!$V$5:$V$154,0)),"") -> 46291 | E17: =IFERROR(INDEX('Clients & Pipeline'!$Q$5:$Q$154,MATCH(4,'Clients & Pipeline'!$V$5:$V$154,0)),"") -> Due this week | G17: =IFERROR(INDEX('Invoices & Follow-ups'!$B$5:$B$204,MATCH(4,'Invoices & Follow-ups'!$T$5:$T$204,0)),"") -> Northfield Accounting | H17: =IFERROR(INDEX('Invoices & Follow-ups'!$A$5:$A$204,MATCH(4,'Invoices & Follow-ups'!$T$5:$T$204,0)),"") -> 2026-020 | I17: =IFERROR(INDEX('Invoices & Follow-ups'!$J$5:$J$204,MATCH(4,'Invoices & Follow-ups'!$T$5:$T$204,0)),"") -> 2600 | J17: =IFERROR(INDEX('Invoices & Follow-ups'!$Q$5:$Q$204,MATCH(4,'Invoices & Follow-ups'!$T$5:$T$204,0)),"") -> Send A now
B18: =IFERROR(INDEX('Clients & Pipeline'!$B$5:$B$154,MATCH(5,'Clients & Pipeline'!$V$5:$V$154,0)),"") -> Northfield Accounting | C18: =IFERROR(INDEX('Clients & Pipeline'!$N$5:$N$154,MATCH(5,'Clients & Pipeline'!$V$5:$V$154,0)),"") -> Kickoff call prep | D18: =IFERROR(INDEX('Clients & Pipeline'!$O$5:$O$154,MATCH(5,'Clients & Pipeline'!$V$5:$V$154,0)),"") -> 46294 | E18: =IFERROR(INDEX('Clients & Pipeline'!$Q$5:$Q$154,MATCH(5,'Clients & Pipeline'!$V$5:$V$154,0)),"") -> Due this week | G18: =IFERROR(INDEX('Invoices & Follow-ups'!$B$5:$B$204,MATCH(5,'Invoices & Follow-ups'!$T$5:$T$204,0)),"") | H18: =IFERROR(INDEX('Invoices & Follow-ups'!$A$5:$A$204,MATCH(5,'Invoices & Follow-ups'!$T$5:$T$204,0)),"") | I18: =IFERROR(INDEX('Invoices & Follow-ups'!$J$5:$J$204,MATCH(5,'Invoices & Follow-ups'!$T$5:$T$204,0)),"") | J18: =IFERROR(INDEX('Invoices & Follow-ups'!$Q$5:$Q$204,MATCH(5,'Invoices & Follow-ups'!$T$5:$T$204,0)),"")
B19: =IFERROR(INDEX('Clients & Pipeline'!$B$5:$B$154,MATCH(6,'Clients & Pipeline'!$V$5:$V$154,0)),"") -> Maple Street Bakery | C19: =IFERROR(INDEX('Clients & Pipeline'!$N$5:$N$154,MATCH(6,'Clients & Pipeline'!$V$5:$V$154,0)),"") -> 90-day check-in email | D19: =IFERROR(INDEX('Clients & Pipeline'!$O$5:$O$154,MATCH(6,'Clients & Pipeline'!$V$5:$V$154,0)),"") -> 46299 | E19: =IFERROR(INDEX('Clients & Pipeline'!$Q$5:$Q$154,MATCH(6,'Clients & Pipeline'!$V$5:$V$154,0)),"") -> Upcoming | G19: =IFERROR(INDEX('Invoices & Follow-ups'!$B$5:$B$204,MATCH(6,'Invoices & Follow-ups'!$T$5:$T$204,0)),"") | H19: =IFERROR(INDEX('Invoices & Follow-ups'!$A$5:$A$204,MATCH(6,'Invoices & Follow-ups'!$T$5:$T$204,0)),"") | I19: =IFERROR(INDEX('Invoices & Follow-ups'!$J$5:$J$204,MATCH(6,'Invoices & Follow-ups'!$T$5:$T$204,0)),"") | J19: =IFERROR(INDEX('Invoices & Follow-ups'!$Q$5:$Q$204,MATCH(6,'Invoices & Follow-ups'!$T$5:$T$204,0)),"")
B20: =IFERROR(INDEX('Clients & Pipeline'!$B$5:$B$154,MATCH(7,'Clients & Pipeline'!$V$5:$V$154,0)),"") | C20: =IFERROR(INDEX('Clients & Pipeline'!$N$5:$N$154,MATCH(7,'Clients & Pipeline'!$V$5:$V$154,0)),"") | D20: =IFERROR(INDEX('Clients & Pipeline'!$O$5:$O$154,MATCH(7,'Clients & Pipeline'!$V$5:$V$154,0)),"") | E20: =IFERROR(INDEX('Clients & Pipeline'!$Q$5:$Q$154,MATCH(7,'Clients & Pipeline'!$V$5:$V$154,0)),"") | G20: =IFERROR(INDEX('Invoices & Follow-ups'!$B$5:$B$204,MATCH(7,'Invoices & Follow-ups'!$T$5:$T$204,0)),"") | H20: =IFERROR(INDEX('Invoices & Follow-ups'!$A$5:$A$204,MATCH(7,'Invoices & Follow-ups'!$T$5:$T$204,0)),"") | I20: =IFERROR(INDEX('Invoices & Follow-ups'!$J$5:$J$204,MATCH(7,'Invoices & Follow-ups'!$T$5:$T$204,0)),"") | J20: =IFERROR(INDEX('Invoices & Follow-ups'!$Q$5:$Q$204,MATCH(7,'Invoices & Follow-ups'!$T$5:$T$204,0)),"")
B21: =IFERROR(INDEX('Clients & Pipeline'!$B$5:$B$154,MATCH(8,'Clients & Pipeline'!$V$5:$V$154,0)),"") | C21: =IFERROR(INDEX('Clients & Pipeline'!$N$5:$N$154,MATCH(8,'Clients & Pipeline'!$V$5:$V$154,0)),"") | D21: =IFERROR(INDEX('Clients & Pipeline'!$O$5:$O$154,MATCH(8,'Clients & Pipeline'!$V$5:$V$154,0)),"") | E21: =IFERROR(INDEX('Clients & Pipeline'!$Q$5:$Q$154,MATCH(8,'Clients & Pipeline'!$V$5:$V$154,0)),"") | G21: =IFERROR(INDEX('Invoices & Follow-ups'!$B$5:$B$204,MATCH(8,'Invoices & Follow-ups'!$T$5:$T$204,0)),"") | H21: =IFERROR(INDEX('Invoices & Follow-ups'!$A$5:$A$204,MATCH(8,'Invoices & Follow-ups'!$T$5:$T$204,0)),"") | I21: =IFERROR(INDEX('Invoices & Follow-ups'!$J$5:$J$204,MATCH(8,'Invoices & Follow-ups'!$T$5:$T$204,0)),"") | J21: =IFERROR(INDEX('Invoices & Follow-ups'!$Q$5:$Q$204,MATCH(8,'Invoices & Follow-ups'!$T$5:$T$204,0)),"")
B24: Top admin tasks to fix first | G24: Clients by stage
B25: Task | C25: Minutes / month | D25: Priority | E25: Decision | G25: Stage | H25: Clients | I25: Value
B26: =IFERROR(INDEX('Admin Audit'!$A$5:$A$44,MATCH(1,'Admin Audit'!$I$5:$I$44,0)),"") -> Weekly client updates | C26: =IFERROR(INDEX('Admin Audit'!$E$5:$E$44,MATCH(1,'Admin Audit'!$I$5:$I$44,0)),"") -> 320 | D26: =IFERROR(INDEX('Admin Audit'!$H$5:$H$44,MATCH(1,'Admin Audit'!$I$5:$I$44,0)),"") -> 960 | E26: =IFERROR(INDEX('Admin Audit'!$J$5:$J$44,MATCH(1,'Admin Audit'!$I$5:$I$44,0)),"") -> Template | G26: =Settings!$E$14 -> 1 · Inquiry | H26: =COUNTIF('Clients & Pipeline'!$G$5:$G$154,G26) -> 1 | I26: =SUMIFS('Clients & Pipeline'!$H$5:$H$154,'Clients & Pipeline'!$G$5:$G$154,G26) -> 400
B27: =IFERROR(INDEX('Admin Audit'!$A$5:$A$44,MATCH(2,'Admin Audit'!$I$5:$I$44,0)),"") -> Social media posts | C27: =IFERROR(INDEX('Admin Audit'!$E$5:$E$44,MATCH(2,'Admin Audit'!$I$5:$I$44,0)),"") -> 240 | D27: =IFERROR(INDEX('Admin Audit'!$H$5:$H$44,MATCH(2,'Admin Audit'!$I$5:$I$44,0)),"") -> 480 | E27: =IFERROR(INDEX('Admin Audit'!$J$5:$J$44,MATCH(2,'Admin Audit'!$I$5:$I$44,0)),"") -> AI draft | G27: =Settings!$E$15 -> 2 · Discovery | H27: =COUNTIF('Clients & Pipeline'!$G$5:$G$154,G27) -> 1 | I27: =SUMIFS('Clients & Pipeline'!$H$5:$H$154,'Clients & Pipeline'!$G$5:$G$154,G27) -> 1200
B28: =IFERROR(INDEX('Admin Audit'!$A$5:$A$44,MATCH(3,'Admin Audit'!$I$5:$I$44,0)),"") -> Replying to inquiries | C28: =IFERROR(INDEX('Admin Audit'!$E$5:$E$44,MATCH(3,'Admin Audit'!$I$5:$I$44,0)),"") -> 120 | D28: =IFERROR(INDEX('Admin Audit'!$H$5:$H$44,MATCH(3,'Admin Audit'!$I$5:$I$44,0)),"") -> 360 | E28: =IFERROR(INDEX('Admin Audit'!$J$5:$J$44,MATCH(3,'Admin Audit'!$I$5:$I$44,0)),"") -> Template | G28: =Settings!$E$16 -> 3 · Proposal sent | H28: =COUNTIF('Clients & Pipeline'!$G$5:$G$154,G28) -> 1 | I28: =SUMIFS('Clients & Pipeline'!$H$5:$H$154,'Clients & Pipeline'!$G$5:$G$154,G28) -> 6500
G29: =Settings!$E$17 -> 4 · Onboarding | H29: =COUNTIF('Clients & Pipeline'!$G$5:$G$154,G29) -> 1 | I29: =SUMIFS('Clients & Pipeline'!$H$5:$H$154,'Clients & Pipeline'!$G$5:$G$154,G29) -> 5200
G30: =Settings!$E$18 -> 5 · Delivery | H30: =COUNTIF('Clients & Pipeline'!$G$5:$G$154,G30) -> 1 | I30: =SUMIFS('Clients & Pipeline'!$H$5:$H$154,'Clients & Pipeline'!$G$5:$G$154,G30) -> 4800
G31: =Settings!$E$19 -> 6 · Wrap-up & payment | H31: =COUNTIF('Clients & Pipeline'!$G$5:$G$154,G31) -> 0 | I31: =SUMIFS('Clients & Pipeline'!$H$5:$H$154,'Clients & Pipeline'!$G$5:$G$154,G31) -> 0
G32: =Settings!$E$20 -> 7 · Past client | H32: =COUNTIF('Clients & Pipeline'!$G$5:$G$154,G32) -> 1 | I32: =SUMIFS('Clients & Pipeline'!$H$5:$H$154,'Clients & Pipeline'!$G$5:$G$154,G32) -> 3900
G33: =Settings!$E$21 -> Lost | H33: =COUNTIF('Clients & Pipeline'!$G$5:$G$154,G33) -> 1 | I33: =SUMIFS('Clients & Pipeline'!$H$5:$H$154,'Clients & Pipeline'!$G$5:$G$154,G33) -> 3000
G35: Tip: sort or filter the other tabs any time. The dashboard reads the whole range.

Sheet Clients & Pipeline
A1: Clients & Pipeline
A2: One row per client or lead. Update the Stage and Next action date and everything else calculates.
A3: Yellow cells = type here · Grey cells = calculated (don't type) · Slate headers = helper columns
A4: Client ID | B4: Client / company | C4: Contact name | D4: Email | E4: Service | F4: Source | G4: Stage | H4: Project value | I4: Win % | J4: Weighted value | K4: Group | L4: First contact | M4: Proposal sent | N4: Next action | O4: Next action date | P4: Days until next action | Q4: Action status | R4: Project end date | S4: 90-day check-in | T4: Notes | U4: Active flag | V4: Action rank
A5: =IF(B5="","","C"&TEXT(ROW()-4,"000")) -> C001 | B5: Harbor Dental Studio | C5: Dr. Lee (fictional) | D5: office@example.com | E5: Website design | F5: Referral | G5: 5 · Delivery | H5: 4800 | I5: =IF(OR(B5="",G5=""),"",INDEX(Settings!$F$14:$F$21,MATCH(G5,Settings!$E$14:$E$21,0))) -> 1 | J5: =IF(OR(I5="",H5=""),"",H5*I5) -> 4800 | K5: =IF(OR(B5="",G5=""),"",INDEX(Settings!$G$14:$G$21,MATCH(G5,Settings!$E$14:$E$21,0))) -> Active | L5: =Settings!$C$6-60 -> 46229 | M5: =Settings!$C$6-45 -> 46244 | N5: Send weekly update | O5: =Settings!$C$6+2 -> 46291 | P5: =IF(OR(B5="",O5="",G5="Lost"),"",O5-Settings!$C$6) -> 2 | Q5: =IF(P5="","",IF(P5<0,"Overdue",IF(P5<=7,"Due this week","Upcoming"))) -> Due this week | S5: =IF(AND(G5="7 · Past client",R5<>""),R5+90,"") | T5: SAMPLE | U5: =IF(P5="",0,1) -> 1 | V5: =IF(U5=0,"",COUNTIFS($U$5:$U$154,1,$O$5:$O$154,"<"&O5)+COUNTIFS($U$5:$U5,1,$O$5:$O5,O5)) -> 3
A6: =IF(B6="","","C"&TEXT(ROW()-4,"000")) -> C002 | B6: Oak & Pine Law | C6: J. Patel (fictional) | D6: jp@example.com | E6: Website design | F6: LinkedIn | G6: 3 · Proposal sent | H6: 6500 | I6: =IF(OR(B6="",G6=""),"",INDEX(Settings!$F$14:$F$21,MATCH(G6,Settings!$E$14:$E$21,0))) -> 0.5 | J6: =IF(OR(I6="",H6=""),"",H6*I6) -> 3250 | K6: =IF(OR(B6="",G6=""),"",INDEX(Settings!$G$14:$G$21,MATCH(G6,Settings!$E$14:$E$21,0))) -> Pipeline | L6: =Settings!$C$6-12 -> 46277 | M6: =Settings!$C$6-5 -> 46284 | N6: Proposal follow-up (day 7) | O6: =Settings!$C$6+2 -> 46291 | P6: =IF(OR(B6="",O6="",G6="Lost"),"",O6-Settings!$C$6) -> 2 | Q6: =IF(P6="","",IF(P6<0,"Overdue",IF(P6<=7,"Due this week","Upcoming"))) -> Due this week | S6: =IF(AND(G6="7 · Past client",R6<>""),R6+90,"") | T6: SAMPLE | U6: =IF(P6="",0,1) -> 1 | V6: =IF(U6=0,"",COUNTIFS($U$5:$U$154,1,$O$5:$O$154,"<"&O6)+COUNTIFS($U$5:$U6,1,$O$5:$O6,O6)) -> 4
A7: =IF(B7="","","C"&TEXT(ROW()-4,"000")) -> C003 | B7: Brightside Physio | C7: M. Chen (fictional) | D7: hello@example.com | E7: Website care plan | F7: Website | G7: 2 · Discovery | H7: 1200 | I7: =IF(OR(B7="",G7=""),"",INDEX(Settings!$F$14:$F$21,MATCH(G7,Settings!$E$14:$E$21,0))) -> 0.25 | J7: =IF(OR(I7="",H7=""),"",H7*I7) -> 300 | K7: =IF(OR(B7="",G7=""),"",INDEX(Settings!$G$14:$G$21,MATCH(G7,Settings!$E$14:$E$21,0))) -> Pipeline | L7: =Settings!$C$6-4 -> 46285 | N7: Send call summary | O7: =Settings!$C$6-1 -> 46288 | P7: =IF(OR(B7="",O7="",G7="Lost"),"",O7-Settings!$C$6) -> -1 | Q7: =IF(P7="","",IF(P7<0,"Overdue",IF(P7<=7,"Due this week","Upcoming"))) -> Overdue | S7: =IF(AND(G7="7 · Past client",R7<>""),R7+90,"") | T7: SAMPLE | U7: =IF(P7="",0,1) -> 1 | V7: =IF(U7=0,"",COUNTIFS($U$5:$U$154,1,$O$5:$O$154,"<"&O7)+COUNTIFS($U$5:$U7,1,$O$5:$O7,O7)) -> 1
A8: =IF(B8="","","C"&TEXT(ROW()-4,"000")) -> C004 | B8: Northfield Accounting | C8: R. Gomez (fictional) | D8: rg@example.com | E8: Website design | F8: Past client | G8: 4 · Onboarding | H8: 5200 | I8: =IF(OR(B8="",G8=""),"",INDEX(Settings!$F$14:$F$21,MATCH(G8,Settings!$E$14:$E$21,0))) -> 1 | J8: =IF(OR(I8="",H8=""),"",H8*I8) -> 5200 | K8: =IF(OR(B8="",G8=""),"",INDEX(Settings!$G$14:$G$21,MATCH(G8,Settings!$E$14:$E$21,0))) -> Active | L8: =Settings!$C$6-20 -> 46269 | M8: =Settings!$C$6-14 -> 46275 | N8: Kickoff call prep | O8: =Settings!$C$6+5 -> 46294 | P8: =IF(OR(B8="",O8="",G8="Lost"),"",O8-Settings!$C$6) -> 5 | Q8: =IF(P8="","",IF(P8<0,"Overdue",IF(P8<=7,"Due this week","Upcoming"))) -> Due this week | S8: =IF(AND(G8="7 · Past client",R8<>""),R8+90,"") | T8: SAMPLE | U8: =IF(P8="",0,1) -> 1 | V8: =IF(U8=0,"",COUNTIFS($U$5:$U$154,1,$O$5:$O$154,"<"&O8)+COUNTIFS($U$5:$U8,1,$O$5:$O8,O8)) -> 5
A9: =IF(B9="","","C"&TEXT(ROW()-4,"000")) -> C005 | B9: Cedar Yoga | C9: A. Novak (fictional) | D9: studio@example.com | E9: Strategy session | F9: Instagram | G9: 1 · Inquiry | H9: 400 | I9: =IF(OR(B9="",G9=""),"",INDEX(Settings!$F$14:$F$21,MATCH(G9,Settings!$E$14:$E$21,0))) -> 0.1 | J9: =IF(OR(I9="",H9=""),"",H9*I9) -> 40 | K9: =IF(OR(B9="",G9=""),"",INDEX(Settings!$G$14:$G$21,MATCH(G9,Settings!$E$14:$E$21,0))) -> Pipeline | L9: =Settings!$C$6-1 -> 46288 | N9: Reply to inquiry | O9: =Settings!$C$6 -> 46289 | P9: =IF(OR(B9="",O9="",G9="Lost"),"",O9-Settings!$C$6) -> 0 | Q9: =IF(P9="","",IF(P9<0,"Overdue",IF(P9<=7,"Due this week","Upcoming"))) -> Due this week | S9: =IF(AND(G9="7 · Past client",R9<>""),R9+90,"") | T9: SAMPLE | U9: =IF(P9="",0,1) -> 1 | V9: =IF(U9=0,"",COUNTIFS($U$5:$U$154,1,$O$5:$O$154,"<"&O9)+COUNTIFS($U$5:$U9,1,$O$5:$O9,O9)) -> 2
A10: =IF(B10="","","C"&TEXT(ROW()-4,"000")) -> C006 | B10: Maple Street Bakery | C10: T. Brown (fictional) | D10: tb@example.com | E10: Website design | F10: Referral | G10: 7 · Past client | H10: 3900 | I10: =IF(OR(B10="",G10=""),"",INDEX(Settings!$F$14:$F$21,MATCH(G10,Settings!$E$14:$E$21,0))) -> 0 | J10: =IF(OR(I10="",H10=""),"",H10*I10) -> 0 | K10: =IF(OR(B10="",G10=""),"",INDEX(Settings!$G$14:$G$21,MATCH(G10,Settings!$E$14:$E$21,0))) -> Closed | L10: =Settings!$C$6-200 -> 46089 | M10: =Settings!$C$6-190 -> 46099 | N10: 90-day check-in email | O10: =Settings!$C$6+10 -> 46299 | P10: =IF(OR(B10="",O10="",G10="Lost"),"",O10-Settings!$C$6) -> 10 | Q10: =IF(P10="","",IF(P10<0,"Overdue",IF(P10<=7,"Due this week","Upcoming"))) -> Upcoming | R10: =Settings!$C$6-80 -> 46209 | S10: =IF(AND(G10="7 · Past client",R10<>""),R10+90,"") -> 46299 | T10: SAMPLE | U10: =IF(P10="",0,1) -> 1 | V10: =IF(U10=0,"",COUNTIFS($U$5:$U$154,1,$O$5:$O$154,"<"&O10)+COUNTIFS($U$5:$U10,1,$O$5:$O10,O10)) -> 6
A11: =IF(B11="","","C"&TEXT(ROW()-4,"000")) -> C007 | B11: Summit Coaching | C11: K. Ito (fictional) | D11: ki@example.com | E11: Website design | F11: Website | G11: Lost | H11: 3000 | I11: =IF(OR(B11="",G11=""),"",INDEX(Settings!$F$14:$F$21,MATCH(G11,Settings!$E$14:$E$21,0))) -> 0 | J11: =IF(OR(I11="",H11=""),"",H11*I11) -> 0 | K11: =IF(OR(B11="",G11=""),"",INDEX(Settings!$G$14:$G$21,MATCH(G11,Settings!$E$14:$E$21,0))) -> Closed | L11: =Settings!$C$6-90 -> 46199 | M11: =Settings!$C$6-80 -> 46209 | P11: =IF(OR(B11="",O11="",G11="Lost"),"",O11-Settings!$C$6) | Q11: =IF(P11="","",IF(P11<0,"Overdue",IF(P11<=7,"Due this week","Upcoming"))) | S11: =IF(AND(G11="7 · Past client",R11<>""),R11+90,"") | T11: SAMPLE: chose a cheaper option | U11: =IF(P11="",0,1) -> 0 | V11: =IF(U11=0,"",COUNTIFS($U$5:$U$154,1,$O$5:$O$154,"<"&O11)+COUNTIFS($U$5:$U11,1,$O$5:$O11,O11))
A12: =IF(B12="","","C"&TEXT(ROW()-4,"000")) | I12: =IF(OR(B12="",G12=""),"",INDEX(Settings!$F$14:$F$21,MATCH(G12,Settings!$E$14:$E$21,0))) | J12: =IF(OR(I12="",H12=""),"",H12*I12) | K12: =IF(OR(B12="",G12=""),"",INDEX(Settings!$G$14:$G$21,MATCH(G12,Settings!$E$14:$E$21,0))) | P12: =IF(OR(B12="",O12="",G12="Lost"),"",O12-Settings!$C$6) | Q12: =IF(P12="","",IF(P12<0,"Overdue",IF(P12<=7,"Due this week","Upcoming"))) | S12: =IF(AND(G12="7 · Past client",R12<>""),R12+90,"") | U12: =IF(P12="",0,1) -> 0 | V12: =IF(U12=0,"",COUNTIFS($U$5:$U$154,1,$O$5:$O$154,"<"&O12)+COUNTIFS($U$5:$U12,1,$O$5:$O12,O12))
A13: =IF(B13="","","C"&TEXT(ROW()-4,"000")) | I13: =IF(OR(B13="",G13=""),"",INDEX(Settings!$F$14:$F$21,MATCH(G13,Settings!$E$14:$E$21,0))) | J13: =IF(OR(I13="",H13=""),"",H13*I13) | K13: =IF(OR(B13="",G13=""),"",INDEX(Settings!$G$14:$G$21,MATCH(G13,Settings!$E$14:$E$21,0))) | P13: =IF(OR(B13="",O13="",G13="Lost"),"",O13-Settings!$C$6) | Q13: =IF(P13="","",IF(P13<0,"Overdue",IF(P13<=7,"Due this week","Upcoming"))) | S13: =IF(AND(G13="7 · Past client",R13<>""),R13+90,"") | U13: =IF(P13="",0,1) -> 0 | V13: =IF(U13=0,"",COUNTIFS($U$5:$U$154,1,$O$5:$O$154,"<"&O13)+COUNTIFS($U$5:$U13,1,$O$5:$O13,O13))
A14: =IF(B14="","","C"&TEXT(ROW()-4,"000")) | I14: =IF(OR(B14="",G14=""),"",INDEX(Settings!$F$14:$F$21,MATCH(G14,Settings!$E$14:$E$21,0))) | J14: =IF(OR(I14="",H14=""),"",H14*I14) | K14: =IF(OR(B14="",G14=""),"",INDEX(Settings!$G$14:$G$21,MATCH(G14,Settings!$E$14:$E$21,0))) | P14: =IF(OR(B14="",O14="",G14="Lost"),"",O14-Settings!$C$6) | Q14: =IF(P14="","",IF(P14<0,"Overdue",IF(P14<=7,"Due this week","Upcoming"))) | S14: =IF(AND(G14="7 · Past client",R14<>""),R14+90,"") | U14: =IF(P14="",0,1) -> 0 | V14: =IF(U14=0,"",COUNTIFS($U$5:$U$154,1,$O$5:$O$154,"<"&O14)+COUNTIFS($U$5:$U14,1,$O$5:$O14,O14))
A15: =IF(B15="","","C"&TEXT(ROW()-4,"000")) | I15: =IF(OR(B15="",G15=""),"",INDEX(Settings!$F$14:$F$21,MATCH(G15,Settings!$E$14:$E$21,0))) | J15: =IF(OR(I15="",H15=""),"",H15*I15) | K15: =IF(OR(B15="",G15=""),"",INDEX(Settings!$G$14:$G$21,MATCH(G15,Settings!$E$14:$E$21,0))) | P15: =IF(OR(B15="",O15="",G15="Lost"),"",O15-Settings!$C$6) | Q15: =IF(P15="","",IF(P15<0,"Overdue",IF(P15<=7,"Due this week","Upcoming"))) | S15: =IF(AND(G15="7 · Past client",R15<>""),R15+90,"") | U15: =IF(P15="",0,1) -> 0 | V15: =IF(U15=0,"",COUNTIFS($U$5:$U$154,1,$O$5:$O$154,"<"&O15)+COUNTIFS($U$5:$U15,1,$O$5:$O15,O15))
A16: =IF(B16="","","C"&TEXT(ROW()-4,"000")) | I16: =IF(OR(B16="",G16=""),"",INDEX(Settings!$F$14:$F$21,MATCH(G16,Settings!$E$14:$E$21,0))) | J16: =IF(OR(I16="",H16=""),"",H16*I16) | K16: =IF(OR(B16="",G16=""),"",INDEX(Settings!$G$14:$G$21,MATCH(G16,Settings!$E$14:$E$21,0))) | P16: =IF(OR(B16="",O16="",G16="Lost"),"",O16-Settings!$C$6) | Q16: =IF(P16="","",IF(P16<0,"Overdue",IF(P16<=7,"Due this week","Upcoming"))) | S16: =IF(AND(G16="7 · Past client",R16<>""),R16+90,"") | U16: =IF(P16="",0,1) -> 0 | V16: =IF(U16=0,"",COUNTIFS($U$5:$U$154,1,$O$5:$O$154,"<"&O16)+COUNTIFS($U$5:$U16,1,$O$5:$O16,O16))
A17: =IF(B17="","","C"&TEXT(ROW()-4,"000")) | I17: =IF(OR(B17="",G17=""),"",INDEX(Settings!$F$14:$F$21,MATCH(G17,Settings!$E$14:$E$21,0))) | J17: =IF(OR(I17="",H17=""),"",H17*I17) | K17: =IF(OR(B17="",G17=""),"",INDEX(Settings!$G$14:$G$21,MATCH(G17,Settings!$E$14:$E$21,0))) | P17: =IF(OR(B17="",O17="",G17="Lost"),"",O17-Settings!$C$6) | Q17: =IF(P17="","",IF(P17<0,"Overdue",IF(P17<=7,"Due this week","Upcoming"))) | S17: =IF(AND(G17="7 · Past client",R17<>""),R17+90,"") | U17: =IF(P17="",0,1) -> 0 | V17: =IF(U17=0,"",COUNTIFS($U$5:$U$154,1,$O$5:$O$154,"<"&O17)+COUNTIFS($U$5:$U17,1,$O$5:$O17,O17))
A18: =IF(B18="","","C"&TEXT(ROW()-4,"000")) | I18: =IF(OR(B18="",G18=""),"",INDEX(Settings!$F$14:$F$21,MATCH(G18,Settings!$E$14:$E$21,0))) | J18: =IF(OR(I18="",H18=""),"",H18*I18) | K18: =IF(OR(B18="",G18=""),"",INDEX(Settings!$G$14:$G$21,MATCH(G18,Settings!$E$14:$E$21,0))) | P18: =IF(OR(B18="",O18="",G18="Lost"),"",O18-Settings!$C$6) | Q18: =IF(P18="","",IF(P18<0,"Overdue",IF(P18<=7,"Due this week","Upcoming"))) | S18: =IF(AND(G18="7 · Past client",R18<>""),R18+90,"") | U18: =IF(P18="",0,1) -> 0 | V18: =IF(U18=0,"",COUNTIFS($U$5:$U$154,1,$O$5:$O$154,"<"&O18)+COUNTIFS($U$5:$U18,1,$O$5:$O18,O18))
A19: =IF(B19="","","C"&TEXT(ROW()-4,"000")) | I19: =IF(OR(B19="",G19=""),"",INDEX(Settings!$F$14:$F$21,MATCH(G19,Settings!$E$14:$E$21,0))) | J19: =IF(OR(I19="",H19=""),"",H19*I19) | K19: =IF(OR(B19="",G19=""),"",INDEX(Settings!$G$14:$G$21,MATCH(G19,Settings!$E$14:$E$21,0))) | P19: =IF(OR(B19="",O19="",G19="Lost"),"",O19-Settings!$C$6) | Q19: =IF(P19="","",IF(P19<0,"Overdue",IF(P19<=7,"Due this week","Upcoming"))) | S19: =IF(AND(G19="7 · Past client",R19<>""),R19+90,"") | U19: =IF(P19="",0,1) -> 0 | V19: =IF(U19=0,"",COUNTIFS($U$5:$U$154,1,$O$5:$O$154,"<"&O19)+COUNTIFS($U$5:$U19,1,$O$5:$O19,O19))
A20: =IF(B20="","","C"&TEXT(ROW()-4,"000")) | I20: =IF(OR(B20="",G20=""),"",INDEX(Settings!$F$14:$F$21,MATCH(G20,Settings!$E$14:$E$21,0))) | J20: =IF(OR(I20="",H20=""),"",H20*I20) | K20: =IF(OR(B20="",G20=""),"",INDEX(Settings!$G$14:$G$21,MATCH(G20,Settings!$E$14:$E$21,0))) | P20: =IF(OR(B20="",O20="",G20="Lost"),"",O20-Settings!$C$6) | Q20: =IF(P20="","",IF(P20<0,"Overdue",IF(P20<=7,"Due this week","Upcoming"))) | S20: =IF(AND(G20="7 · Past client",R20<>""),R20+90,"") | U20: =IF(P20="",0,1) -> 0 | V20: =IF(U20=0,"",COUNTIFS($U$5:$U$154,1,$O$5:$O$154,"<"&O20)+COUNTIFS($U$5:$U20,1,$O$5:$O20,O20))
A21: =IF(B21="","","C"&TEXT(ROW()-4,"000")) | I21: =IF(OR(B21="",G21=""),"",INDEX(Settings!$F$14:$F$21,MATCH(G21,Settings!$E$14:$E$21,0))) | J21: =IF(OR(I21="",H21=""),"",H21*I21) | K21: =IF(OR(B21="",G21=""),"",INDEX(Settings!$G$14:$G$21,MATCH(G21,Settings!$E$14:$E$21,0))) | P21: =IF(OR(B21="",O21="",G21="Lost"),"",O21-Settings!$C$6) | Q21: =IF(P21="","",IF(P21<0,"Overdue",IF(P21<=7,"Due this week","Upcoming"))) | S21: =IF(AND(G21="7 · Past client",R21<>""),R21+90,"") | U21: =IF(P21="",0,1) -> 0 | V21: =IF(U21=0,"",COUNTIFS($U$5:$U$154,1,$O$5:$O$154,"<"&O21)+COUNTIFS($U$5:$U21,1,$O$5:$O21,O21))
A22: =IF(B22="","","C"&TEXT(ROW()-4,"000")) | I22: =IF(OR(B22="",G22=""),"",INDEX(Settings!$F$14:$F$21,MATCH(G22,Settings!$E$14:$E$21,0))) | J22: =IF(OR(I22="",H22=""),"",H22*I22) | K22: =IF(OR(B22="",G22=""),"",INDEX(Settings!$G$14:$G$21,MATCH(G22,Settings!$E$14:$E$21,0))) | P22: =IF(OR(B22="",O22="",G22="Lost"),"",O22-Settings!$C$6) | Q22: =IF(P22="","",IF(P22<0,"Overdue",IF(P22<=7,"Due this week","Upcoming"))) | S22: =IF(AND(G22="7 · Past client",R22<>""),R22+90,"") | U22: =IF(P22="",0,1) -> 0 | V22: =IF(U22=0,"",COUNTIFS($U$5:$U$154,1,$O$5:$O$154,"<"&O22)+COUNTIFS($U$5:$U22,1,$O$5:$O22,O22))
A23: =IF(B23="","","C"&TEXT(ROW()-4,"000")) | I23: =IF(OR(B23="",G23=""),"",INDEX(Settings!$F$14:$F$21,MATCH(G23,Settings!$E$14:$E$21,0))) | J23: =IF(OR(I23="",H23=""),"",H23*I23) | K23: =IF(OR(B23="",G23=""),"",INDEX(Settings!$G$14:$G$21,MATCH(G23,Settings!$E$14:$E$21,0))) | P23: =IF(OR(B23="",O23="",G23="Lost"),"",O23-Settings!$C$6) | Q23: =IF(P23="","",IF(P23<0,"Overdue",IF(P23<=7,"Due this week","Upcoming"))) | S23: =IF(AND(G23="7 · Past client",R23<>""),R23+90,"") | U23: =IF(P23="",0,1) -> 0 | V23: =IF(U23=0,"",COUNTIFS($U$5:$U$154,1,$O$5:$O$154,"<"&O23)+COUNTIFS($U$5:$U23,1,$O$5:$O23,O23))
... A154: =IF(B154="","","C"&TEXT(ROW()-4,"000")) | I154: =IF(OR(B154="",G154=""),"",INDEX(Settings!$F$14:$F$21,MATCH(G154,Settings!$E$14:$E$21,0))) | J154: =IF(OR(I154="",H154=""),"",H154*I154) | K154: =IF(OR(B154="",G154=""),"",INDEX(Settings!$G$14:$G$21,MATCH(G154,Settings!$E$14:$E$21,0))) | P154: =IF(OR(B154="",O154="",G154="Lost"),"",O154-Settings!$C$6) | Q154: =IF(P154="","",IF(P154<0,"Overdue",IF(P154<=7,"Due this week","Upcoming"))) | S154: =IF(AND(G154="7 · Past client",R154<>""),R154+90,"") | U154: =IF(P154="",0,1) -> 0 | V154: =IF(U154=0,"",COUNTIFS($U$5:$U$154,1,$O$5:$O$154,"<"&O154)+COUNTIFS($U$5:$U154,1,$O$5:$O154,O154))

Sheet Projects
A1: Projects
A2: Track each project's milestones, deposit and weekly update day.
A3: Yellow cells = type here · Grey cells = calculated (don't type) · Slate headers = helper columns
A4: Project | B4: Client | C4: Start date | D4: Due date | E4: Status | F4: Fee | G4: Deposit % | H4: Deposit amount | I4: Next milestone | J4: Milestone date | K4: Days to milestone | L4: Flag | M4: Weekly update day | N4: Notes
A5: Harbor Dental website | B5: Harbor Dental Studio | C5: =Settings!$C$6-40 -> 46249 | D5: =Settings!$C$6+20 -> 46309 | E5: In progress | F5: 4800 | G5: 0.5 | H5: =IF(OR(F5="",G5=""),"",F5*G5) -> 2400 | I5: Homepage design review | J5: =Settings!$C$6+3 -> 46292 | K5: =IF(OR(A5="",J5="",E5="Complete"),"",J5-Settings!$C$6) -> 3 | L5: =IF(K5="","",IF(K5<0,"Overdue",IF(K5<=7,"This week",""))) -> This week | M5: Friday | N5: SAMPLE
A6: Northfield site rebuild | B6: Northfield Accounting | C6: =Settings!$C$6+2 -> 46291 | D6: =Settings!$C$6+50 -> 46339 | E6: Not started | F6: 5200 | G6: 0.5 | H6: =IF(OR(F6="",G6=""),"",F6*G6) -> 2600 | I6: Kickoff call | J6: =Settings!$C$6+5 -> 46294 | K6: =IF(OR(A6="",J6="",E6="Complete"),"",J6-Settings!$C$6) -> 5 | L6: =IF(K6="","",IF(K6<0,"Overdue",IF(K6<=7,"This week",""))) -> This week | M6: Thursday | N6: SAMPLE
A7: Maple Street care plan | B7: Maple Street Bakery | C7: =Settings!$C$6-80 -> 46209 | D7: =Settings!$C$6-10 -> 46279 | E7: Complete | F7: 3900 | G7: 0.5 | H7: =IF(OR(F7="",G7=""),"",F7*G7) -> 1950 | K7: =IF(OR(A7="",J7="",E7="Complete"),"",J7-Settings!$C$6) | L7: =IF(K7="","",IF(K7<0,"Overdue",IF(K7<=7,"This week",""))) | N7: SAMPLE
H8: =IF(OR(F8="",G8=""),"",F8*G8) | K8: =IF(OR(A8="",J8="",E8="Complete"),"",J8-Settings!$C$6) | L8: =IF(K8="","",IF(K8<0,"Overdue",IF(K8<=7,"This week","")))
H9: =IF(OR(F9="",G9=""),"",F9*G9) | K9: =IF(OR(A9="",J9="",E9="Complete"),"",J9-Settings!$C$6) | L9: =IF(K9="","",IF(K9<0,"Overdue",IF(K9<=7,"This week","")))
H10: =IF(OR(F10="",G10=""),"",F10*G10) | K10: =IF(OR(A10="",J10="",E10="Complete"),"",J10-Settings!$C$6) | L10: =IF(K10="","",IF(K10<0,"Overdue",IF(K10<=7,"This week","")))
H11: =IF(OR(F11="",G11=""),"",F11*G11) | K11: =IF(OR(A11="",J11="",E11="Complete"),"",J11-Settings!$C$6) | L11: =IF(K11="","",IF(K11<0,"Overdue",IF(K11<=7,"This week","")))
H12: =IF(OR(F12="",G12=""),"",F12*G12) | K12: =IF(OR(A12="",J12="",E12="Complete"),"",J12-Settings!$C$6) | L12: =IF(K12="","",IF(K12<0,"Overdue",IF(K12<=7,"This week","")))
H13: =IF(OR(F13="",G13=""),"",F13*G13) | K13: =IF(OR(A13="",J13="",E13="Complete"),"",J13-Settings!$C$6) | L13: =IF(K13="","",IF(K13<0,"Overdue",IF(K13<=7,"This week","")))
H14: =IF(OR(F14="",G14=""),"",F14*G14) | K14: =IF(OR(A14="",J14="",E14="Complete"),"",J14-Settings!$C$6) | L14: =IF(K14="","",IF(K14<0,"Overdue",IF(K14<=7,"This week","")))
H15: =IF(OR(F15="",G15=""),"",F15*G15) | K15: =IF(OR(A15="",J15="",E15="Complete"),"",J15-Settings!$C$6) | L15: =IF(K15="","",IF(K15<0,"Overdue",IF(K15<=7,"This week","")))
H16: =IF(OR(F16="",G16=""),"",F16*G16) | K16: =IF(OR(A16="",J16="",E16="Complete"),"",J16-Settings!$C$6) | L16: =IF(K16="","",IF(K16<0,"Overdue",IF(K16<=7,"This week","")))
H17: =IF(OR(F17="",G17=""),"",F17*G17) | K17: =IF(OR(A17="",J17="",E17="Complete"),"",J17-Settings!$C$6) | L17: =IF(K17="","",IF(K17<0,"Overdue",IF(K17<=7,"This week","")))
H18: =IF(OR(F18="",G18=""),"",F18*G18) | K18: =IF(OR(A18="",J18="",E18="Complete"),"",J18-Settings!$C$6) | L18: =IF(K18="","",IF(K18<0,"Overdue",IF(K18<=7,"This week","")))
H19: =IF(OR(F19="",G19=""),"",F19*G19) | K19: =IF(OR(A19="",J19="",E19="Complete"),"",J19-Settings!$C$6) | L19: =IF(K19="","",IF(K19<0,"Overdue",IF(K19<=7,"This week","")))
... H104: =IF(OR(F104="",G104=""),"",F104*G104) | K104: =IF(OR(A104="",J104="",E104="Complete"),"",J104-Settings!$C$6) | L104: =IF(K104="","",IF(K104<0,"Overdue",IF(K104<=7,"This week","")))

Sheet Invoices & Follow-ups
A1: Invoices & Follow-ups
A2: Log each invoice. Due dates, days overdue and the next reminder stage (A–E) calculate automatically.
A3: Yellow cells = type here · Grey cells = calculated (don't type) · Slate headers = helper columns
A4: Invoice # | B4: Client | C4: Description | D4: Issue date | E4: Terms (days) | F4: Due date | G4: Amount | H4: Amount paid | I4: Paid date | J4: Balance | K4: Status | L4: Days overdue | M4: Reminder stage due | N4: Next reminder date | O4: Last reminder sent | P4: Last reminder date | Q4: Action | R4: Notes | S4: Action flag | T4: Action rank
A5: 2026-014 | B5: Harbor Dental Studio | C5: Deposit 50% | D5: =Settings!$C$6-45 -> 46244 | E5: 14 | F5: =IF(D5="","",D5+IF(E5="",Settings!$C$7,E5)) -> 46258 | G5: 2400 | H5: 2400 | I5: =Settings!$C$6-33 -> 46256 | J5: =IF(G5="","",G5-N(H5)) -> 0 | K5: =IF(OR(G5="",F5=""),"",IF(J5<=0,"Paid",IF(Settings!$C$6<F5,IF(N(H5)>0,"Part-paid","Not due"),IF(Settings!$C$6=F5,"Due today","Overdue")))) -> Paid | L5: =IF(OR(G5="",F5=""),"",IF(J5<=0,"",MAX(0,Settings!$C$6-F5))) | M5: =IF(OR(G5="",F5=""),"",IF(J5<=0,"Paid",IF(Settings!$C$6>=F5+Settings!$P$18,"E",IF(Settings!$C$6>=F5+Settings!$P$17,"D",IF(Settings!$C$6>=F5+Settings!$P$16,"C",IF(Settings!$C$6>=F5+Settings!$P$15,"B",IF(Settings!$C$6>=F5+Settings!$P$14,"A","—"))))))) -> Paid | N5: =IF(OR(G5="",F5="",J5<=0),"",IF(Settings!$C$6<F5+Settings!$P$14,F5+Settings!$P$14,IF(Settings!$C$6<F5+Settings!$P$15,F5+Settings!$P$15,IF(Settings!$C$6<F5+Settings!$P$16,F5+Settings!$P$16,IF(Settings!$C$6<F5+Settings!$P$17,F5+Settings!$P$17,IF(Settings!$C$6<F5+Settings!$P$18,F5+Settings!$P$18,"")))))) | Q5: =IF(OR(M5="",M5="Paid",M5="—"),IF(M5="Paid","Paid ✓",""),IF(O5="","Send "&M5&" now",IF(CODE(M5)>CODE(O5),"Send "&M5&" now","Up to date"))) -> Paid ✓ | R5: SAMPLE: paid | S5: =IF(LEFT(Q5,4)="Send",1,0) -> 0 | T5: =IF(S5=0,"",COUNTIFS($S$5:$S$204,1,$F$5:$F$204,"<"&F5)+COUNTIFS($S$5:$S5,1,$F$5:$F5,F5))
A6: 2026-018 | B6: Harbor Dental Studio | C6: Milestone 2: design approved | D6: =Settings!$C$6-22 -> 46267 | E6: 14 | F6: =IF(D6="","",D6+IF(E6="",Settings!$C$7,E6)) -> 46281 | G6: 1200 | J6: =IF(G6="","",G6-N(H6)) -> 1200 | K6: =IF(OR(G6="",F6=""),"",IF(J6<=0,"Paid",IF(Settings!$C$6<F6,IF(N(H6)>0,"Part-paid","Not due"),IF(Settings!$C$6=F6,"Due today","Overdue")))) -> Overdue | L6: =IF(OR(G6="",F6=""),"",IF(J6<=0,"",MAX(0,Settings!$C$6-F6))) -> 8 | M6: =IF(OR(G6="",F6=""),"",IF(J6<=0,"Paid",IF(Settings!$C$6>=F6+Settings!$P$18,"E",IF(Settings!$C$6>=F6+Settings!$P$17,"D",IF(Settings!$C$6>=F6+Settings!$P$16,"C",IF(Settings!$C$6>=F6+Settings!$P$15,"B",IF(Settings!$C$6>=F6+Settings!$P$14,"A","—"))))))) -> C | N6: =IF(OR(G6="",F6="",J6<=0),"",IF(Settings!$C$6<F6+Settings!$P$14,F6+Settings!$P$14,IF(Settings!$C$6<F6+Settings!$P$15,F6+Settings!$P$15,IF(Settings!$C$6<F6+Settings!$P$16,F6+Settings!$P$16,IF(Settings!$C$6<F6+Settings!$P$17,F6+Settings!$P$17,IF(Settings!$C$6<F6+Settings!$P$18,F6+Settings!$P$18,"")))))) -> 46295 | O6: C | P6: =Settings!$C$6-1 -> 46288 | Q6: =IF(OR(M6="",M6="Paid",M6="—"),IF(M6="Paid","Paid ✓",""),IF(O6="","Send "&M6&" now",IF(CODE(M6)>CODE(O6),"Send "&M6&" now","Up to date"))) -> Up to date | R6: SAMPLE: 8 days overdue, stage C sent | S6: =IF(LEFT(Q6,4)="Send",1,0) -> 0 | T6: =IF(S6=0,"",COUNTIFS($S$5:$S$204,1,$F$5:$F$204,"<"&F6)+COUNTIFS($S$5:$S6,1,$F$5:$F6,F6))
A7: 2026-019 | B7: Maple Street Bakery | C7: Care plan: quarter | D7: =Settings!$C$6-44 -> 46245 | E7: 14 | F7: =IF(D7="","",D7+IF(E7="",Settings!$C$7,E7)) -> 46259 | G7: 450 | J7: =IF(G7="","",G7-N(H7)) -> 450 | K7: =IF(OR(G7="",F7=""),"",IF(J7<=0,"Paid",IF(Settings!$C$6<F7,IF(N(H7)>0,"Part-paid","Not due"),IF(Settings!$C$6=F7,"Due today","Overdue")))) -> Overdue | L7: =IF(OR(G7="",F7=""),"",IF(J7<=0,"",MAX(0,Settings!$C$6-F7))) -> 30 | M7: =IF(OR(G7="",F7=""),"",IF(J7<=0,"Paid",IF(Settings!$C$6>=F7+Settings!$P$18,"E",IF(Settings!$C$6>=F7+Settings!$P$17,"D",IF(Settings!$C$6>=F7+Settings!$P$16,"C",IF(Settings!$C$6>=F7+Settings!$P$15,"B",IF(Settings!$C$6>=F7+Settings!$P$14,"A","—"))))))) -> E | N7: =IF(OR(G7="",F7="",J7<=0),"",IF(Settings!$C$6<F7+Settings!$P$14,F7+Settings!$P$14,IF(Settings!$C$6<F7+Settings!$P$15,F7+Settings!$P$15,IF(Settings!$C$6<F7+Settings!$P$16,F7+Settings!$P$16,IF(Settings!$C$6<F7+Settings!$P$17,F7+Settings!$P$17,IF(Settings!$C$6<F7+Settings!$P$18,F7+Settings!$P$18,"")))))) | O7: C | P7: =Settings!$C$6-23 -> 46266 | Q7: =IF(OR(M7="",M7="Paid",M7="—"),IF(M7="Paid","Paid ✓",""),IF(O7="","Send "&M7&" now",IF(CODE(M7)>CODE(O7),"Send "&M7&" now","Up to date"))) -> Send E now | R7: SAMPLE: 30 days overdue → final notice due | S7: =IF(LEFT(Q7,4)="Send",1,0) -> 1 | T7: =IF(S7=0,"",COUNTIFS($S$5:$S$204,1,$F$5:$F$204,"<"&F7)+COUNTIFS($S$5:$S7,1,$F$5:$F7,F7)) -> 1
A8: 2026-020 | B8: Northfield Accounting | C8: Deposit 50% | D8: =Settings!$C$6-12 -> 46277 | E8: 14 | F8: =IF(D8="","",D8+IF(E8="",Settings!$C$7,E8)) -> 46291 | G8: 2600 | J8: =IF(G8="","",G8-N(H8)) -> 2600 | K8: =IF(OR(G8="",F8=""),"",IF(J8<=0,"Paid",IF(Settings!$C$6<F8,IF(N(H8)>0,"Part-paid","Not due"),IF(Settings!$C$6=F8,"Due today","Overdue")))) -> Not due | L8: =IF(OR(G8="",F8=""),"",IF(J8<=0,"",MAX(0,Settings!$C$6-F8))) -> 0 | M8: =IF(OR(G8="",F8=""),"",IF(J8<=0,"Paid",IF(Settings!$C$6>=F8+Settings!$P$18,"E",IF(Settings!$C$6>=F8+Settings!$P$17,"D",IF(Settings!$C$6>=F8+Settings!$P$16,"C",IF(Settings!$C$6>=F8+Settings!$P$15,"B",IF(Settings!$C$6>=F8+Settings!$P$14,"A","—"))))))) -> A | N8: =IF(OR(G8="",F8="",J8<=0),"",IF(Settings!$C$6<F8+Settings!$P$14,F8+Settings!$P$14,IF(Settings!$C$6<F8+Settings!$P$15,F8+Settings!$P$15,IF(Settings!$C$6<F8+Settings!$P$16,F8+Settings!$P$16,IF(Settings!$C$6<F8+Settings!$P$17,F8+Settings!$P$17,IF(Settings!$C$6<F8+Settings!$P$18,F8+Settings!$P$18,"")))))) -> 46291 | Q8: =IF(OR(M8="",M8="Paid",M8="—"),IF(M8="Paid","Paid ✓",""),IF(O8="","Send "&M8&" now",IF(CODE(M8)>CODE(O8),"Send "&M8&" now","Up to date"))) -> Send A now | R8: SAMPLE: due in 2 days → heads-up | S8: =IF(LEFT(Q8,4)="Send",1,0) -> 1 | T8: =IF(S8=0,"",COUNTIFS($S$5:$S$204,1,$F$5:$F$204,"<"&F8)+COUNTIFS($S$5:$S8,1,$F$5:$F8,F8)) -> 4
A9: 2026-021 | B9: Oak & Pine Law | C9: Strategy workshop | D9: =Settings!$C$6-14 -> 46275 | E9: 14 | F9: =IF(D9="","",D9+IF(E9="",Settings!$C$7,E9)) -> 46289 | G9: 600 | J9: =IF(G9="","",G9-N(H9)) -> 600 | K9: =IF(OR(G9="",F9=""),"",IF(J9<=0,"Paid",IF(Settings!$C$6<F9,IF(N(H9)>0,"Part-paid","Not due"),IF(Settings!$C$6=F9,"Due today","Overdue")))) -> Due today | L9: =IF(OR(G9="",F9=""),"",IF(J9<=0,"",MAX(0,Settings!$C$6-F9))) -> 0 | M9: =IF(OR(G9="",F9=""),"",IF(J9<=0,"Paid",IF(Settings!$C$6>=F9+Settings!$P$18,"E",IF(Settings!$C$6>=F9+Settings!$P$17,"D",IF(Settings!$C$6>=F9+Settings!$P$16,"C",IF(Settings!$C$6>=F9+Settings!$P$15,"B",IF(Settings!$C$6>=F9+Settings!$P$14,"A","—"))))))) -> B | N9: =IF(OR(G9="",F9="",J9<=0),"",IF(Settings!$C$6<F9+Settings!$P$14,F9+Settings!$P$14,IF(Settings!$C$6<F9+Settings!$P$15,F9+Settings!$P$15,IF(Settings!$C$6<F9+Settings!$P$16,F9+Settings!$P$16,IF(Settings!$C$6<F9+Settings!$P$17,F9+Settings!$P$17,IF(Settings!$C$6<F9+Settings!$P$18,F9+Settings!$P$18,"")))))) -> 46296 | O9: A | P9: =Settings!$C$6-3 -> 46286 | Q9: =IF(OR(M9="",M9="Paid",M9="—"),IF(M9="Paid","Paid ✓",""),IF(O9="","Send "&M9&" now",IF(CODE(M9)>CODE(O9),"Send "&M9&" now","Up to date"))) -> Send B now | R9: SAMPLE: due today | S9: =IF(LEFT(Q9,4)="Send",1,0) -> 1 | T9: =IF(S9=0,"",COUNTIFS($S$5:$S$204,1,$F$5:$F$204,"<"&F9)+COUNTIFS($S$5:$S9,1,$F$5:$F9,F9)) -> 3
A10: 2026-022 | B10: Brightside Physio | C10: Audit call | D10: =Settings!$C$6-2 -> 46287 | E10: 14 | F10: =IF(D10="","",D10+IF(E10="",Settings!$C$7,E10)) -> 46301 | G10: 250 | H10: 100 | I10: =Settings!$C$6-1 -> 46288 | J10: =IF(G10="","",G10-N(H10)) -> 150 | K10: =IF(OR(G10="",F10=""),"",IF(J10<=0,"Paid",IF(Settings!$C$6<F10,IF(N(H10)>0,"Part-paid","Not due"),IF(Settings!$C$6=F10,"Due today","Overdue")))) -> Part-paid | L10: =IF(OR(G10="",F10=""),"",IF(J10<=0,"",MAX(0,Settings!$C$6-F10))) -> 0 | M10: =IF(OR(G10="",F10=""),"",IF(J10<=0,"Paid",IF(Settings!$C$6>=F10+Settings!$P$18,"E",IF(Settings!$C$6>=F10+Settings!$P$17,"D",IF(Settings!$C$6>=F10+Settings!$P$16,"C",IF(Settings!$C$6>=F10+Settings!$P$15,"B",IF(Settings!$C$6>=F10+Settings!$P$14,"A","—"))))))) -> — | N10: =IF(OR(G10="",F10="",J10<=0),"",IF(Settings!$C$6<F10+Settings!$P$14,F10+Settings!$P$14,IF(Settings!$C$6<F10+Settings!$P$15,F10+Settings!$P$15,IF(Settings!$C$6<F10+Settings!$P$16,F10+Settings!$P$16,IF(Settings!$C$6<F10+Settings!$P$17,F10+Settings!$P$17,IF(Settings!$C$6<F10+Settings!$P$18,F10+Settings!$P$18,"")))))) -> 46298 | Q10: =IF(OR(M10="",M10="Paid",M10="—"),IF(M10="Paid","Paid ✓",""),IF(O10="","Send "&M10&" now",IF(CODE(M10)>CODE(O10),"Send "&M10&" now","Up to date"))) | R10: SAMPLE: part-paid, not due | S10: =IF(LEFT(Q10,4)="Send",1,0) -> 0 | T10: =IF(S10=0,"",COUNTIFS($S$5:$S$204,1,$F$5:$F$204,"<"&F10)+COUNTIFS($S$5:$S10,1,$F$5:$F10,F10))
A11: 2026-023 | B11: Harbor Dental Studio | C11: Hosting setup | D11: =Settings!$C$6-29 -> 46260 | E11: 14 | F11: =IF(D11="","",D11+IF(E11="",Settings!$C$7,E11)) -> 46274 | G11: 180 | J11: =IF(G11="","",G11-N(H11)) -> 180 | K11: =IF(OR(G11="",F11=""),"",IF(J11<=0,"Paid",IF(Settings!$C$6<F11,IF(N(H11)>0,"Part-paid","Not due"),IF(Settings!$C$6=F11,"Due today","Overdue")))) -> Overdue | L11: =IF(OR(G11="",F11=""),"",IF(J11<=0,"",MAX(0,Settings!$C$6-F11))) -> 15 | M11: =IF(OR(G11="",F11=""),"",IF(J11<=0,"Paid",IF(Settings!$C$6>=F11+Settings!$P$18,"E",IF(Settings!$C$6>=F11+Settings!$P$17,"D",IF(Settings!$C$6>=F11+Settings!$P$16,"C",IF(Settings!$C$6>=F11+Settings!$P$15,"B",IF(Settings!$C$6>=F11+Settings!$P$14,"A","—"))))))) -> D | N11: =IF(OR(G11="",F11="",J11<=0),"",IF(Settings!$C$6<F11+Settings!$P$14,F11+Settings!$P$14,IF(Settings!$C$6<F11+Settings!$P$15,F11+Settings!$P$15,IF(Settings!$C$6<F11+Settings!$P$16,F11+Settings!$P$16,IF(Settings!$C$6<F11+Settings!$P$17,F11+Settings!$P$17,IF(Settings!$C$6<F11+Settings!$P$18,F11+Settings!$P$18,"")))))) -> 46304 | Q11: =IF(OR(M11="",M11="Paid",M11="—"),IF(M11="Paid","Paid ✓",""),IF(O11="","Send "&M11&" now",IF(CODE(M11)>CODE(O11),"Send "&M11&" now","Up to date"))) -> Send D now | R11: SAMPLE: 15 days overdue, no reminder logged | S11: =IF(LEFT(Q11,4)="Send",1,0) -> 1 | T11: =IF(S11=0,"",COUNTIFS($S$5:$S$204,1,$F$5:$F$204,"<"&F11)+COUNTIFS($S$5:$S11,1,$F$5:$F11,F11)) -> 2
F12: =IF(D12="","",D12+IF(E12="",Settings!$C$7,E12)) | J12: =IF(G12="","",G12-N(H12)) | K12: =IF(OR(G12="",F12=""),"",IF(J12<=0,"Paid",IF(Settings!$C$6<F12,IF(N(H12)>0,"Part-paid","Not due"),IF(Settings!$C$6=F12,"Due today","Overdue")))) | L12: =IF(OR(G12="",F12=""),"",IF(J12<=0,"",MAX(0,Settings!$C$6-F12))) | M12: =IF(OR(G12="",F12=""),"",IF(J12<=0,"Paid",IF(Settings!$C$6>=F12+Settings!$P$18,"E",IF(Settings!$C$6>=F12+Settings!$P$17,"D",IF(Settings!$C$6>=F12+Settings!$P$16,"C",IF(Settings!$C$6>=F12+Settings!$P$15,"B",IF(Settings!$C$6>=F12+Settings!$P$14,"A","—"))))))) | N12: =IF(OR(G12="",F12="",J12<=0),"",IF(Settings!$C$6<F12+Settings!$P$14,F12+Settings!$P$14,IF(Settings!$C$6<F12+Settings!$P$15,F12+Settings!$P$15,IF(Settings!$C$6<F12+Settings!$P$16,F12+Settings!$P$16,IF(Settings!$C$6<F12+Settings!$P$17,F12+Settings!$P$17,IF(Settings!$C$6<F12+Settings!$P$18,F12+Settings!$P$18,"")))))) | Q12: =IF(OR(M12="",M12="Paid",M12="—"),IF(M12="Paid","Paid ✓",""),IF(O12="","Send "&M12&" now",IF(CODE(M12)>CODE(O12),"Send "&M12&" now","Up to date"))) | S12: =IF(LEFT(Q12,4)="Send",1,0) -> 0 | T12: =IF(S12=0,"",COUNTIFS($S$5:$S$204,1,$F$5:$F$204,"<"&F12)+COUNTIFS($S$5:$S12,1,$F$5:$F12,F12))
F13: =IF(D13="","",D13+IF(E13="",Settings!$C$7,E13)) | J13: =IF(G13="","",G13-N(H13)) | K13: =IF(OR(G13="",F13=""),"",IF(J13<=0,"Paid",IF(Settings!$C$6<F13,IF(N(H13)>0,"Part-paid","Not due"),IF(Settings!$C$6=F13,"Due today","Overdue")))) | L13: =IF(OR(G13="",F13=""),"",IF(J13<=0,"",MAX(0,Settings!$C$6-F13))) | M13: =IF(OR(G13="",F13=""),"",IF(J13<=0,"Paid",IF(Settings!$C$6>=F13+Settings!$P$18,"E",IF(Settings!$C$6>=F13+Settings!$P$17,"D",IF(Settings!$C$6>=F13+Settings!$P$16,"C",IF(Settings!$C$6>=F13+Settings!$P$15,"B",IF(Settings!$C$6>=F13+Settings!$P$14,"A","—"))))))) | N13: =IF(OR(G13="",F13="",J13<=0),"",IF(Settings!$C$6<F13+Settings!$P$14,F13+Settings!$P$14,IF(Settings!$C$6<F13+Settings!$P$15,F13+Settings!$P$15,IF(Settings!$C$6<F13+Settings!$P$16,F13+Settings!$P$16,IF(Settings!$C$6<F13+Settings!$P$17,F13+Settings!$P$17,IF(Settings!$C$6<F13+Settings!$P$18,F13+Settings!$P$18,"")))))) | Q13: =IF(OR(M13="",M13="Paid",M13="—"),IF(M13="Paid","Paid ✓",""),IF(O13="","Send "&M13&" now",IF(CODE(M13)>CODE(O13),"Send "&M13&" now","Up to date"))) | S13: =IF(LEFT(Q13,4)="Send",1,0) -> 0 | T13: =IF(S13=0,"",COUNTIFS($S$5:$S$204,1,$F$5:$F$204,"<"&F13)+COUNTIFS($S$5:$S13,1,$F$5:$F13,F13))
F14: =IF(D14="","",D14+IF(E14="",Settings!$C$7,E14)) | J14: =IF(G14="","",G14-N(H14)) | K14: =IF(OR(G14="",F14=""),"",IF(J14<=0,"Paid",IF(Settings!$C$6<F14,IF(N(H14)>0,"Part-paid","Not due"),IF(Settings!$C$6=F14,"Due today","Overdue")))) | L14: =IF(OR(G14="",F14=""),"",IF(J14<=0,"",MAX(0,Settings!$C$6-F14))) | M14: =IF(OR(G14="",F14=""),"",IF(J14<=0,"Paid",IF(Settings!$C$6>=F14+Settings!$P$18,"E",IF(Settings!$C$6>=F14+Settings!$P$17,"D",IF(Settings!$C$6>=F14+Settings!$P$16,"C",IF(Settings!$C$6>=F14+Settings!$P$15,"B",IF(Settings!$C$6>=F14+Settings!$P$14,"A","—"))))))) | N14: =IF(OR(G14="",F14="",J14<=0),"",IF(Settings!$C$6<F14+Settings!$P$14,F14+Settings!$P$14,IF(Settings!$C$6<F14+Settings!$P$15,F14+Settings!$P$15,IF(Settings!$C$6<F14+Settings!$P$16,F14+Settings!$P$16,IF(Settings!$C$6<F14+Settings!$P$17,F14+Settings!$P$17,IF(Settings!$C$6<F14+Settings!$P$18,F14+Settings!$P$18,"")))))) | Q14: =IF(OR(M14="",M14="Paid",M14="—"),IF(M14="Paid","Paid ✓",""),IF(O14="","Send "&M14&" now",IF(CODE(M14)>CODE(O14),"Send "&M14&" now","Up to date"))) | S14: =IF(LEFT(Q14,4)="Send",1,0) -> 0 | T14: =IF(S14=0,"",COUNTIFS($S$5:$S$204,1,$F$5:$F$204,"<"&F14)+COUNTIFS($S$5:$S14,1,$F$5:$F14,F14))
F15: =IF(D15="","",D15+IF(E15="",Settings!$C$7,E15)) | J15: =IF(G15="","",G15-N(H15)) | K15: =IF(OR(G15="",F15=""),"",IF(J15<=0,"Paid",IF(Settings!$C$6<F15,IF(N(H15)>0,"Part-paid","Not due"),IF(Settings!$C$6=F15,"Due today","Overdue")))) | L15: =IF(OR(G15="",F15=""),"",IF(J15<=0,"",MAX(0,Settings!$C$6-F15))) | M15: =IF(OR(G15="",F15=""),"",IF(J15<=0,"Paid",IF(Settings!$C$6>=F15+Settings!$P$18,"E",IF(Settings!$C$6>=F15+Settings!$P$17,"D",IF(Settings!$C$6>=F15+Settings!$P$16,"C",IF(Settings!$C$6>=F15+Settings!$P$15,"B",IF(Settings!$C$6>=F15+Settings!$P$14,"A","—"))))))) | N15: =IF(OR(G15="",F15="",J15<=0),"",IF(Settings!$C$6<F15+Settings!$P$14,F15+Settings!$P$14,IF(Settings!$C$6<F15+Settings!$P$15,F15+Settings!$P$15,IF(Settings!$C$6<F15+Settings!$P$16,F15+Settings!$P$16,IF(Settings!$C$6<F15+Settings!$P$17,F15+Settings!$P$17,IF(Settings!$C$6<F15+Settings!$P$18,F15+Settings!$P$18,"")))))) | Q15: =IF(OR(M15="",M15="Paid",M15="—"),IF(M15="Paid","Paid ✓",""),IF(O15="","Send "&M15&" now",IF(CODE(M15)>CODE(O15),"Send "&M15&" now","Up to date"))) | S15: =IF(LEFT(Q15,4)="Send",1,0) -> 0 | T15: =IF(S15=0,"",COUNTIFS($S$5:$S$204,1,$F$5:$F$204,"<"&F15)+COUNTIFS($S$5:$S15,1,$F$5:$F15,F15))
F16: =IF(D16="","",D16+IF(E16="",Settings!$C$7,E16)) | J16: =IF(G16="","",G16-N(H16)) | K16: =IF(OR(G16="",F16=""),"",IF(J16<=0,"Paid",IF(Settings!$C$6<F16,IF(N(H16)>0,"Part-paid","Not due"),IF(Settings!$C$6=F16,"Due today","Overdue")))) | L16: =IF(OR(G16="",F16=""),"",IF(J16<=0,"",MAX(0,Settings!$C$6-F16))) | M16: =IF(OR(G16="",F16=""),"",IF(J16<=0,"Paid",IF(Settings!$C$6>=F16+Settings!$P$18,"E",IF(Settings!$C$6>=F16+Settings!$P$17,"D",IF(Settings!$C$6>=F16+Settings!$P$16,"C",IF(Settings!$C$6>=F16+Settings!$P$15,"B",IF(Settings!$C$6>=F16+Settings!$P$14,"A","—"))))))) | N16: =IF(OR(G16="",F16="",J16<=0),"",IF(Settings!$C$6<F16+Settings!$P$14,F16+Settings!$P$14,IF(Settings!$C$6<F16+Settings!$P$15,F16+Settings!$P$15,IF(Settings!$C$6<F16+Settings!$P$16,F16+Settings!$P$16,IF(Settings!$C$6<F16+Settings!$P$17,F16+Settings!$P$17,IF(Settings!$C$6<F16+Settings!$P$18,F16+Settings!$P$18,"")))))) | Q16: =IF(OR(M16="",M16="Paid",M16="—"),IF(M16="Paid","Paid ✓",""),IF(O16="","Send "&M16&" now",IF(CODE(M16)>CODE(O16),"Send "&M16&" now","Up to date"))) | S16: =IF(LEFT(Q16,4)="Send",1,0) -> 0 | T16: =IF(S16=0,"",COUNTIFS($S$5:$S$204,1,$F$5:$F$204,"<"&F16)+COUNTIFS($S$5:$S16,1,$F$5:$F16,F16))
F17: =IF(D17="","",D17+IF(E17="",Settings!$C$7,E17)) | J17: =IF(G17="","",G17-N(H17)) | K17: =IF(OR(G17="",F17=""),"",IF(J17<=0,"Paid",IF(Settings!$C$6<F17,IF(N(H17)>0,"Part-paid","Not due"),IF(Settings!$C$6=F17,"Due today","Overdue")))) | L17: =IF(OR(G17="",F17=""),"",IF(J17<=0,"",MAX(0,Settings!$C$6-F17))) | M17: =IF(OR(G17="",F17=""),"",IF(J17<=0,"Paid",IF(Settings!$C$6>=F17+Settings!$P$18,"E",IF(Settings!$C$6>=F17+Settings!$P$17,"D",IF(Settings!$C$6>=F17+Settings!$P$16,"C",IF(Settings!$C$6>=F17+Settings!$P$15,"B",IF(Settings!$C$6>=F17+Settings!$P$14,"A","—"))))))) | N17: =IF(OR(G17="",F17="",J17<=0),"",IF(Settings!$C$6<F17+Settings!$P$14,F17+Settings!$P$14,IF(Settings!$C$6<F17+Settings!$P$15,F17+Settings!$P$15,IF(Settings!$C$6<F17+Settings!$P$16,F17+Settings!$P$16,IF(Settings!$C$6<F17+Settings!$P$17,F17+Settings!$P$17,IF(Settings!$C$6<F17+Settings!$P$18,F17+Settings!$P$18,"")))))) | Q17: =IF(OR(M17="",M17="Paid",M17="—"),IF(M17="Paid","Paid ✓",""),IF(O17="","Send "&M17&" now",IF(CODE(M17)>CODE(O17),"Send "&M17&" now","Up to date"))) | S17: =IF(LEFT(Q17,4)="Send",1,0) -> 0 | T17: =IF(S17=0,"",COUNTIFS($S$5:$S$204,1,$F$5:$F$204,"<"&F17)+COUNTIFS($S$5:$S17,1,$F$5:$F17,F17))
F18: =IF(D18="","",D18+IF(E18="",Settings!$C$7,E18)) | J18: =IF(G18="","",G18-N(H18)) | K18: =IF(OR(G18="",F18=""),"",IF(J18<=0,"Paid",IF(Settings!$C$6<F18,IF(N(H18)>0,"Part-paid","Not due"),IF(Settings!$C$6=F18,"Due today","Overdue")))) | L18: =IF(OR(G18="",F18=""),"",IF(J18<=0,"",MAX(0,Settings!$C$6-F18))) | M18: =IF(OR(G18="",F18=""),"",IF(J18<=0,"Paid",IF(Settings!$C$6>=F18+Settings!$P$18,"E",IF(Settings!$C$6>=F18+Settings!$P$17,"D",IF(Settings!$C$6>=F18+Settings!$P$16,"C",IF(Settings!$C$6>=F18+Settings!$P$15,"B",IF(Settings!$C$6>=F18+Settings!$P$14,"A","—"))))))) | N18: =IF(OR(G18="",F18="",J18<=0),"",IF(Settings!$C$6<F18+Settings!$P$14,F18+Settings!$P$14,IF(Settings!$C$6<F18+Settings!$P$15,F18+Settings!$P$15,IF(Settings!$C$6<F18+Settings!$P$16,F18+Settings!$P$16,IF(Settings!$C$6<F18+Settings!$P$17,F18+Settings!$P$17,IF(Settings!$C$6<F18+Settings!$P$18,F18+Settings!$P$18,"")))))) | Q18: =IF(OR(M18="",M18="Paid",M18="—"),IF(M18="Paid","Paid ✓",""),IF(O18="","Send "&M18&" now",IF(CODE(M18)>CODE(O18),"Send "&M18&" now","Up to date"))) | S18: =IF(LEFT(Q18,4)="Send",1,0) -> 0 | T18: =IF(S18=0,"",COUNTIFS($S$5:$S$204,1,$F$5:$F$204,"<"&F18)+COUNTIFS($S$5:$S18,1,$F$5:$F18,F18))
F19: =IF(D19="","",D19+IF(E19="",Settings!$C$7,E19)) | J19: =IF(G19="","",G19-N(H19)) | K19: =IF(OR(G19="",F19=""),"",IF(J19<=0,"Paid",IF(Settings!$C$6<F19,IF(N(H19)>0,"Part-paid","Not due"),IF(Settings!$C$6=F19,"Due today","Overdue")))) | L19: =IF(OR(G19="",F19=""),"",IF(J19<=0,"",MAX(0,Settings!$C$6-F19))) | M19: =IF(OR(G19="",F19=""),"",IF(J19<=0,"Paid",IF(Settings!$C$6>=F19+Settings!$P$18,"E",IF(Settings!$C$6>=F19+Settings!$P$17,"D",IF(Settings!$C$6>=F19+Settings!$P$16,"C",IF(Settings!$C$6>=F19+Settings!$P$15,"B",IF(Settings!$C$6>=F19+Settings!$P$14,"A","—"))))))) | N19: =IF(OR(G19="",F19="",J19<=0),"",IF(Settings!$C$6<F19+Settings!$P$14,F19+Settings!$P$14,IF(Settings!$C$6<F19+Settings!$P$15,F19+Settings!$P$15,IF(Settings!$C$6<F19+Settings!$P$16,F19+Settings!$P$16,IF(Settings!$C$6<F19+Settings!$P$17,F19+Settings!$P$17,IF(Settings!$C$6<F19+Settings!$P$18,F19+Settings!$P$18,"")))))) | Q19: =IF(OR(M19="",M19="Paid",M19="—"),IF(M19="Paid","Paid ✓",""),IF(O19="","Send "&M19&" now",IF(CODE(M19)>CODE(O19),"Send "&M19&" now","Up to date"))) | S19: =IF(LEFT(Q19,4)="Send",1,0) -> 0 | T19: =IF(S19=0,"",COUNTIFS($S$5:$S$204,1,$F$5:$F$204,"<"&F19)+COUNTIFS($S$5:$S19,1,$F$5:$F19,F19))
F20: =IF(D20="","",D20+IF(E20="",Settings!$C$7,E20)) | J20: =IF(G20="","",G20-N(H20)) | K20: =IF(OR(G20="",F20=""),"",IF(J20<=0,"Paid",IF(Settings!$C$6<F20,IF(N(H20)>0,"Part-paid","Not due"),IF(Settings!$C$6=F20,"Due today","Overdue")))) | L20: =IF(OR(G20="",F20=""),"",IF(J20<=0,"",MAX(0,Settings!$C$6-F20))) | M20: =IF(OR(G20="",F20=""),"",IF(J20<=0,"Paid",IF(Settings!$C$6>=F20+Settings!$P$18,"E",IF(Settings!$C$6>=F20+Settings!$P$17,"D",IF(Settings!$C$6>=F20+Settings!$P$16,"C",IF(Settings!$C$6>=F20+Settings!$P$15,"B",IF(Settings!$C$6>=F20+Settings!$P$14,"A","—"))))))) | N20: =IF(OR(G20="",F20="",J20<=0),"",IF(Settings!$C$6<F20+Settings!$P$14,F20+Settings!$P$14,IF(Settings!$C$6<F20+Settings!$P$15,F20+Settings!$P$15,IF(Settings!$C$6<F20+Settings!$P$16,F20+Settings!$P$16,IF(Settings!$C$6<F20+Settings!$P$17,F20+Settings!$P$17,IF(Settings!$C$6<F20+Settings!$P$18,F20+Settings!$P$18,"")))))) | Q20: =IF(OR(M20="",M20="Paid",M20="—"),IF(M20="Paid","Paid ✓",""),IF(O20="","Send "&M20&" now",IF(CODE(M20)>CODE(O20),"Send "&M20&" now","Up to date"))) | S20: =IF(LEFT(Q20,4)="Send",1,0) -> 0 | T20: =IF(S20=0,"",COUNTIFS($S$5:$S$204,1,$F$5:$F$204,"<"&F20)+COUNTIFS($S$5:$S20,1,$F$5:$F20,F20))
F21: =IF(D21="","",D21+IF(E21="",Settings!$C$7,E21)) | J21: =IF(G21="","",G21-N(H21)) | K21: =IF(OR(G21="",F21=""),"",IF(J21<=0,"Paid",IF(Settings!$C$6<F21,IF(N(H21)>0,"Part-paid","Not due"),IF(Settings!$C$6=F21,"Due today","Overdue")))) | L21: =IF(OR(G21="",F21=""),"",IF(J21<=0,"",MAX(0,Settings!$C$6-F21))) | M21: =IF(OR(G21="",F21=""),"",IF(J21<=0,"Paid",IF(Settings!$C$6>=F21+Settings!$P$18,"E",IF(Settings!$C$6>=F21+Settings!$P$17,"D",IF(Settings!$C$6>=F21+Settings!$P$16,"C",IF(Settings!$C$6>=F21+Settings!$P$15,"B",IF(Settings!$C$6>=F21+Settings!$P$14,"A","—"))))))) | N21: =IF(OR(G21="",F21="",J21<=0),"",IF(Settings!$C$6<F21+Settings!$P$14,F21+Settings!$P$14,IF(Settings!$C$6<F21+Settings!$P$15,F21+Settings!$P$15,IF(Settings!$C$6<F21+Settings!$P$16,F21+Settings!$P$16,IF(Settings!$C$6<F21+Settings!$P$17,F21+Settings!$P$17,IF(Settings!$C$6<F21+Settings!$P$18,F21+Settings!$P$18,"")))))) | Q21: =IF(OR(M21="",M21="Paid",M21="—"),IF(M21="Paid","Paid ✓",""),IF(O21="","Send "&M21&" now",IF(CODE(M21)>CODE(O21),"Send "&M21&" now","Up to date"))) | S21: =IF(LEFT(Q21,4)="Send",1,0) -> 0 | T21: =IF(S21=0,"",COUNTIFS($S$5:$S$204,1,$F$5:$F$204,"<"&F21)+COUNTIFS($S$5:$S21,1,$F$5:$F21,F21))
F22: =IF(D22="","",D22+IF(E22="",Settings!$C$7,E22)) | J22: =IF(G22="","",G22-N(H22)) | K22: =IF(OR(G22="",F22=""),"",IF(J22<=0,"Paid",IF(Settings!$C$6<F22,IF(N(H22)>0,"Part-paid","Not due"),IF(Settings!$C$6=F22,"Due today","Overdue")))) | L22: =IF(OR(G22="",F22=""),"",IF(J22<=0,"",MAX(0,Settings!$C$6-F22))) | M22: =IF(OR(G22="",F22=""),"",IF(J22<=0,"Paid",IF(Settings!$C$6>=F22+Settings!$P$18,"E",IF(Settings!$C$6>=F22+Settings!$P$17,"D",IF(Settings!$C$6>=F22+Settings!$P$16,"C",IF(Settings!$C$6>=F22+Settings!$P$15,"B",IF(Settings!$C$6>=F22+Settings!$P$14,"A","—"))))))) | N22: =IF(OR(G22="",F22="",J22<=0),"",IF(Settings!$C$6<F22+Settings!$P$14,F22+Settings!$P$14,IF(Settings!$C$6<F22+Settings!$P$15,F22+Settings!$P$15,IF(Settings!$C$6<F22+Settings!$P$16,F22+Settings!$P$16,IF(Settings!$C$6<F22+Settings!$P$17,F22+Settings!$P$17,IF(Settings!$C$6<F22+Settings!$P$18,F22+Settings!$P$18,"")))))) | Q22: =IF(OR(M22="",M22="Paid",M22="—"),IF(M22="Paid","Paid ✓",""),IF(O22="","Send "&M22&" now",IF(CODE(M22)>CODE(O22),"Send "&M22&" now","Up to date"))) | S22: =IF(LEFT(Q22,4)="Send",1,0) -> 0 | T22: =IF(S22=0,"",COUNTIFS($S$5:$S$204,1,$F$5:$F$204,"<"&F22)+COUNTIFS($S$5:$S22,1,$F$5:$F22,F22))
F23: =IF(D23="","",D23+IF(E23="",Settings!$C$7,E23)) | J23: =IF(G23="","",G23-N(H23)) | K23: =IF(OR(G23="",F23=""),"",IF(J23<=0,"Paid",IF(Settings!$C$6<F23,IF(N(H23)>0,"Part-paid","Not due"),IF(Settings!$C$6=F23,"Due today","Overdue")))) | L23: =IF(OR(G23="",F23=""),"",IF(J23<=0,"",MAX(0,Settings!$C$6-F23))) | M23: =IF(OR(G23="",F23=""),"",IF(J23<=0,"Paid",IF(Settings!$C$6>=F23+Settings!$P$18,"E",IF(Settings!$C$6>=F23+Settings!$P$17,"D",IF(Settings!$C$6>=F23+Settings!$P$16,"C",IF(Settings!$C$6>=F23+Settings!$P$15,"B",IF(Settings!$C$6>=F23+Settings!$P$14,"A","—"))))))) | N23: =IF(OR(G23="",F23="",J23<=0),"",IF(Settings!$C$6<F23+Settings!$P$14,F23+Settings!$P$14,IF(Settings!$C$6<F23+Settings!$P$15,F23+Settings!$P$15,IF(Settings!$C$6<F23+Settings!$P$16,F23+Settings!$P$16,IF(Settings!$C$6<F23+Settings!$P$17,F23+Settings!$P$17,IF(Settings!$C$6<F23+Settings!$P$18,F23+Settings!$P$18,"")))))) | Q23: =IF(OR(M23="",M23="Paid",M23="—"),IF(M23="Paid","Paid ✓",""),IF(O23="","Send "&M23&" now",IF(CODE(M23)>CODE(O23),"Send "&M23&" now","Up to date"))) | S23: =IF(LEFT(Q23,4)="Send",1,0) -> 0 | T23: =IF(S23=0,"",COUNTIFS($S$5:$S$204,1,$F$5:$F$204,"<"&F23)+COUNTIFS($S$5:$S23,1,$F$5:$F23,F23))
... F204: =IF(D204="","",D204+IF(E204="",Settings!$C$7,E204)) | J204: =IF(G204="","",G204-N(H204)) | K204: =IF(OR(G204="",F204=""),"",IF(J204<=0,"Paid",IF(Settings!$C$6<F204,IF(N(H204)>0,"Part-paid","Not due"),IF(Settings!$C$6=F204,"Due today","Overdue")))) | L204: =IF(OR(G204="",F204=""),"",IF(J204<=0,"",MAX(0,Settings!$C$6-F204))) | M204: =IF(OR(G204="",F204=""),"",IF(J204<=0,"Paid",IF(Settings!$C$6>=F204+Settings!$P$18,"E",IF(Settings!$C$6>=F204+Settings!$P$17,"D",IF(Settings!$C$6>=F204+Settings!$P$16,"C",IF(Settings!$C$6>=F204+Settings!$P$15,"B",IF(Settings!$C$6>=F204+Settings!$P$14,"A","—"))))))) | N204: =IF(OR(G204="",F204="",J204<=0),"",IF(Settings!$C$6<F204+Settings!$P$14,F204+Settings!$P$14,IF(Settings!$C$6<F204+Settings!$P$15,F204+Settings!$P$15,IF(Settings!$C$6<F204+Settings!$P$16,F204+Settings!$P$16,IF(Settings!$C$6<F204+Settings!$P$17,F204+Settings!$P$17,IF(Settings!$C$6<F204+Settings!$P$18,F204+Settings!$P$18,"")))))) | Q204: =IF(OR(M204="",M204="Paid",M204="—"),IF(M204="Paid","Paid ✓",""),IF(O204="","Send "&M204&" now",IF(CODE(M204)>CODE(O204),"Send "&M204&" now","Up to date"))) | S204: =IF(LEFT(Q204,4)="Send",1,0) -> 0 | T204: =IF(S204=0,"",COUNTIFS($S$5:$S$204,1,$F$5:$F$204,"<"&F204)+COUNTIFS($S$5:$S204,1,$F$5:$F204,F204))

Sheet Admin Audit
A1: Admin Audit
A2: List recurring admin tasks. Priority = (times/month × minutes) × repeatability ÷ risk. Fix the top-ranked tasks first.
A3: Yellow cells = type here · Grey cells = calculated (don't type) · Slate headers = helper columns
